<?xml version="1.0" ?>
<!-- =================================================================================== -->
<!-- |    This document was autogenerated by xacro from /home/jordi/svn/stacks/reem_common/reem_description/robots/reem_right_hand_marker.urdf.xacro | -->
<!-- |    EDITING THIS FILE BY HAND IS NOT RECOMMENDED                                 | -->
<!-- =================================================================================== -->
<!--

  Copyright (c) 2011, PAL Robotics, S.L.
  All rights reserved.

  This work is licensed under the Creative Commons Attribution-NonCommercial-NoDerivs 3.0 Unported License.
  To view a copy of this license, visit http://creativecommons.org/licenses/by-nc-nd/3.0/ or send a letter to
  Creative Commons, 444 Castro Street, Suite 900, Mountain View, California, 94041, USA.
-->
<robot name="reem" xmlns:controller="http://playerstage.sourceforge.net/gazebo/xmlschema/#controller" xmlns:interface="http://playerstage.sourceforge.net/gazebo/xmlschema/#interface" xmlns:sensor="http://playerstage.sourceforge.net/gazebo/xmlschema/#sensor" xmlns:xacro="http://ros.org/wiki/xacro">
  <!-- The following included files set up definitions of parts of the robot body -->
  <!-- Base -->
  <!-- Torso -->
  <!-- Head -->
  <!-- Arm -->
  <!-- Hand -->
  <!-- Hand Marker-->
  <!-- Camera sensors -->
  <!-- Generic simulator_gazebo plugins -->
  <gazebo>
    <plugin filename="libPalModelPlugin.so" name="pal_model_plugin">
      <plugin_params>
        <pin_link>torso_2_link</pin_link>
      </plugin_params>
    </plugin>
    <plugin filename="libgazebo_ros_controller_manager.so" name="gazebo_ros_controller_manager">
      <alwaysOn>true</alwaysOn>
      <updateRate>1000.0</updateRate>
    </plugin>
  </gazebo>
  <!-- Materials for visualization -->
  <material name="Blue">
    <color rgba="0.0 0.0 0.8 1.0"/>
  </material>
  <material name="Green">
    <color rgba="0.0 0.8 0.0 1.0"/>
  </material>
  <material name="Grey">
    <color rgba="0.7 0.7 0.7 1.0"/>
  </material>
  <material name="LightGrey">
    <color rgba="0.9 0.9 0.9 1.0"/>
  </material>
  <material name="DarkGrey">
    <color rgba="0.2 0.2 0.2 1.0"/>
  </material>
  <material name="Red">
    <color rgba="0.8 0.0 0.0 1.0"/>
  </material>
  <material name="White">
    <color rgba="1.0 1.0 1.0 1.0"/>
  </material>
  <!-- Now we can start using the macros included above to define the actual robot -->
  <link name="base_link">
    <inertial>
      <origin rpy="0 0 0" xyz="-0.14527 -0.00003 0.24721"/>
      <!-- assuming d=0.6, w=0.5, h=0.4 -->
      <mass value="63.58850"/>
      <inertia ixx="3.42" ixy="0" ixz="0" iyy="4.33" iyz="0" izz="5.08"/>
      <!-- assuming d=0.6, w=0.5, h=0.4 -->
      <!--         <origin xyz="-0.15006 -0.00031 0.24965" rpy="0 0 0" /> -->
      <!--         <mass value="64.063" /> -->
      <!-- NOTE: Assuming box with d=0.6, w=0.5, h=0.4 -->
      <!--         <inertia ixx="3.42"  ixy="0"  ixz="0" iyy="4.33" iyz="0" izz="5.08" /> -->
    </inertial>
    <visual>
      <origin rpy="0 0 0" xyz="0 0 0"/>
      <geometry>
        <mesh filename="package://reem_description/meshes/base/base.dae"/>
      </geometry>
      <material name="LightGrey"/>
    </visual>
    <collision>
      <origin rpy="0 0 0" xyz="0 0 0"/>
      <geometry>
        <mesh filename="package://reem_description/meshes/base/base_collision.stl"/>
      </geometry>
      <material name="LightGrey"/>
    </collision>
  </link>
  <link name="base_footprint">
    <visual>
      <origin rpy="0 0 0" xyz="0 0 0.2"/>
      <geometry>
        <box size="0.01 0.01 0.01"/>
      </geometry>
      <material name="White"/>
    </visual>
    <collision>
      <origin rpy="0 0 0" xyz="0 0 0.2"/>
      <geometry>
        <box size="0.001 0.001 0.001"/>
      </geometry>
    </collision>
  </link>
  <joint name="base_footprint_joint" type="fixed">
    <origin rpy="0 0 0" xyz="0 0 0"/>
    <child link="base_link"/>
    <parent link="base_footprint"/>
  </joint>
  <link name="base_center">
    <inertial>
      <mass value="1.0"/>
      <origin xyz="-0.0 0 0"/>
      <inertia ixx="0.01" ixy="0.0" ixz="0.0" iyy="0.01" iyz="0.0" izz="0.01"/>
    </inertial>
    <visual>
      <origin rpy="0 0 0" xyz="-0.0 0 0"/>
      <geometry>
        <box size="0.01 0.01 0.01"/>
      </geometry>
      <material name="White"/>
    </visual>
    <collision>
      <origin rpy="0 0 0" xyz="-0.0 0 0.2"/>
      <geometry>
        <box size="0.001 0.001 0.001"/>
      </geometry>
    </collision>
  </link>
  <joint name="base_center_joint" type="fixed">
    <origin rpy="0 0 0" xyz="-0.195 0 0"/>
    <child link="base_center"/>
    <parent link="base_link"/>
  </joint>
  <link name="base_laser_link" type="laser">
    <inertial>
      <mass value="1"/>
      <origin rpy="0 0 0" xyz="0 0 0"/>
      <inertia ixx="0.0001" ixy="0" ixz="0" iyy="0.000001" iyz="0" izz="0.0001"/>
    </inertial>
    <visual>
      <origin rpy="0 0 0" xyz="0 0 0"/>
      <geometry>
        <box size="0.05 0.05 0.05"/>
      </geometry>
      <material name="DarkGrey"/>
    </visual>
    <collision>
      <origin rpy="0 0 0" xyz="0 0 0"/>
      <geometry>
        <box size=".05 .05 .05"/>
      </geometry>
    </collision>
  </link>
  <joint name="base_laser_joint" type="fixed">
    <axis xyz="0 1 0"/>
    <origin rpy="0 0 0" xyz="0.1 0.0 0.08"/>
    <parent link="base_link"/>
    <child link="base_laser_link"/>
  </joint>
  <gazebo reference="base_laser_link">
    <sensor name="base_laser" type="ray">
      <pose>0 0 0 0 0 0</pose>
      <update_rate>20</update_rate>
      <visualize>true</visualize>
      <ray>
        <scan>
          <horizontal>
            <samples>513</samples>
            <resolution>1</resolution>
            <min_angle>-1.45</min_angle>
            <max_angle>1.45</max_angle>
          </horizontal>
        </scan>
        <range>
          <min>0.08</min>
          <max>10.0</max>
          <resolution>0.01</resolution>
        </range>
      </ray>
      <plugin filename="libgazebo_ros_laser.so" name="gazebo_ros_sick_laser">
        <gaussianNoise>0.005</gaussianNoise>
        <alwaysOn>true</alwaysOn>
        <updateRate>20</updateRate>
        <topicName>/LMS1xx/LAS_00</topicName>
        <frameName>base_laser_link</frameName>
      </plugin>
    </sensor>
  </gazebo>
  <link name="base_torso_laser_link" type="laser">
    <inertial>
      <mass value="1"/>
      <origin rpy="0 0 0" xyz="0 0 0"/>
      <inertia ixx="0.0001" ixy="0" ixz="0" iyy="0.000001" iyz="0" izz="0.0001"/>
    </inertial>
    <visual>
      <origin rpy="0 0 0" xyz="0 0 0"/>
      <geometry>
        <box size="0.05 0.05 0.05"/>
      </geometry>
      <material name="DarkGrey"/>
    </visual>
    <collision>
      <origin rpy="0 0 0" xyz="0 0 0"/>
      <geometry>
        <box size=".05 .05 .05"/>
      </geometry>
    </collision>
  </link>
  <joint name="base_torso_laser_joint" type="revolute">
    <origin rpy="-0.03 0.907571211037 -0.05" xyz="0.04 0 0.745"/>
    <axis xyz="0 1 0"/>
    <parent link="base_link"/>
    <child link="base_torso_laser_link"/>
    <dynamics damping="1.0" friction="1.0"/>
    <limit effort="260" lower="0.0" upper="0.0" velocity="6.0"/>
  </joint>
  <transmission name="hokuyo_fake_trans" type="pr2_mechanism_model/SimpleTransmission">
    <actuator name="base_torso_laser_fake_motor"/>
    <joint name="base_torso_laser_joint"/>
    <mechanicalReduction>1.0</mechanicalReduction>
  </transmission>
  <gazebo reference="base_torso_laser_link">
    <sensor name="base_torso_laser" type="ray">
      <pose>0 0 0 0 0 0</pose>
      <update_rate>10</update_rate>
      <visualize>true</visualize>
      <ray>
        <scan>
          <horizontal>
            <samples>513</samples>
            <resolution>1</resolution>
            <min_angle>-1.35</min_angle>
            <max_angle>1.35</max_angle>
          </horizontal>
        </scan>
        <range>
          <min>0.08</min>
          <max>10.0</max>
          <resolution>0.01</resolution>
        </range>
      </ray>
      <plugin filename="libgazebo_ros_laser.so" name="gazebo_ros_hokuyo_laser">
        <gaussianNoise>0.005</gaussianNoise>
        <alwaysOn>true</alwaysOn>
        <updateRate>10</updateRate>
        <topicName>/hokuyo/LAS_01</topicName>
        <frameName>base_torso_laser_link</frameName>
      </plugin>
    </sensor>
  </gazebo>
  <link name="base_sonar_02_link">
    <inertial>
      <mass value="0.001"/>
      <origin rpy="0 0 0" xyz="0 0 0"/>
      <inertia ixx="0.0001" ixy="0" ixz="0" iyy="0.000001" iyz="0" izz="0.0001"/>
    </inertial>
  </link>
  <joint name="base_sonar_02_joint" type="fixed">
    <origin rpy="0.0 0.0 0.0" xyz="0.17131 0.0 0.280"/>
    <axis xyz="0 0 1"/>
    <parent link="base_link"/>
    <child link="base_sonar_02_link"/>
  </joint>
  <gazebo reference="base_sonar_02_link">
    <sensor name="base_sonar_02" type="ray">
      <pose>0 0 0 0 0 0</pose>
      <update_rate>5</update_rate>
      <visualize>false</visualize>
      <ray>
        <scan>
          <horizontal>
            <samples>5</samples>
            <resolution>1</resolution>
            <min_angle>-0.25</min_angle>
            <max_angle>0.25</max_angle>
          </horizontal>
          <vertical>
            <samples>5</samples>
            <resolution>1</resolution>
            <min_angle>-0.25</min_angle>
            <max_angle>0.25</max_angle>
          </vertical>
        </scan>
        <range>
          <min>0.01</min>
          <max>0.75</max>
          <resolution>0.01</resolution>
        </range>
      </ray>
      <plugin filename="libgazebo_ros_range.so" name="gazebo_ros_range">
        <gaussianNoise>0.005</gaussianNoise>
        <alwaysOn>true</alwaysOn>
        <updateRate>5</updateRate>
        <topicName>sonar_base</topicName>
        <frameName>base_sonar_02_link</frameName>
        <fov>0.5</fov>
        <radiation>ultrasound</radiation>
      </plugin>
    </sensor>
  </gazebo>
  <link name="base_sonar_03_link">
    <inertial>
      <mass value="0.001"/>
      <origin rpy="0 0 0" xyz="0 0 0"/>
      <inertia ixx="0.0001" ixy="0" ixz="0" iyy="0.000001" iyz="0" izz="0.0001"/>
    </inertial>
  </link>
  <joint name="base_sonar_03_joint" type="fixed">
    <origin rpy="0.0 0.0 0.349" xyz="0.16919 0.14919 0.280"/>
    <axis xyz="0 0 1"/>
    <parent link="base_link"/>
    <child link="base_sonar_03_link"/>
  </joint>
  <gazebo reference="base_sonar_03_link">
    <sensor name="base_sonar_03" type="ray">
      <pose>0 0 0 0 0 0</pose>
      <update_rate>5</update_rate>
      <visualize>false</visualize>
      <ray>
        <scan>
          <horizontal>
            <samples>5</samples>
            <resolution>1</resolution>
            <min_angle>-0.25</min_angle>
            <max_angle>0.25</max_angle>
          </horizontal>
          <vertical>
            <samples>5</samples>
            <resolution>1</resolution>
            <min_angle>-0.25</min_angle>
            <max_angle>0.25</max_angle>
          </vertical>
        </scan>
        <range>
          <min>0.01</min>
          <max>0.75</max>
          <resolution>0.01</resolution>
        </range>
      </ray>
      <plugin filename="libgazebo_ros_range.so" name="gazebo_ros_range">
        <gaussianNoise>0.005</gaussianNoise>
        <alwaysOn>true</alwaysOn>
        <updateRate>5</updateRate>
        <topicName>sonar_base</topicName>
        <frameName>base_sonar_03_link</frameName>
        <fov>0.5</fov>
        <radiation>ultrasound</radiation>
      </plugin>
    </sensor>
  </gazebo>
  <link name="base_sonar_01_link">
    <inertial>
      <mass value="0.001"/>
      <origin rpy="0 0 0" xyz="0 0 0"/>
      <inertia ixx="0.0001" ixy="0" ixz="0" iyy="0.000001" iyz="0" izz="0.0001"/>
    </inertial>
  </link>
  <joint name="base_sonar_01_joint" type="fixed">
    <origin rpy="0.0 0.0 -0.349" xyz="0.16919 -0.14919 0.280"/>
    <axis xyz="0 0 1"/>
    <parent link="base_link"/>
    <child link="base_sonar_01_link"/>
  </joint>
  <gazebo reference="base_sonar_01_link">
    <sensor name="base_sonar_01" type="ray">
      <pose>0 0 0 0 0 0</pose>
      <update_rate>5</update_rate>
      <visualize>false</visualize>
      <ray>
        <scan>
          <horizontal>
            <samples>5</samples>
            <resolution>1</resolution>
            <min_angle>-0.25</min_angle>
            <max_angle>0.25</max_angle>
          </horizontal>
          <vertical>
            <samples>5</samples>
            <resolution>1</resolution>
            <min_angle>-0.25</min_angle>
            <max_angle>0.25</max_angle>
          </vertical>
        </scan>
        <range>
          <min>0.01</min>
          <max>0.75</max>
          <resolution>0.01</resolution>
        </range>
      </ray>
      <plugin filename="libgazebo_ros_range.so" name="gazebo_ros_range">
        <gaussianNoise>0.005</gaussianNoise>
        <alwaysOn>true</alwaysOn>
        <updateRate>5</updateRate>
        <topicName>sonar_base</topicName>
        <frameName>base_sonar_01_link</frameName>
        <fov>0.5</fov>
        <radiation>ultrasound</radiation>
      </plugin>
    </sensor>
  </gazebo>
  <link name="base_sonar_04_link">
    <inertial>
      <mass value="0.001"/>
      <origin rpy="0 0 0" xyz="0 0 0"/>
      <inertia ixx="0.0001" ixy="0" ixz="0" iyy="0.000001" iyz="0" izz="0.0001"/>
    </inertial>
  </link>
  <joint name="base_sonar_04_joint" type="fixed">
    <origin rpy="0.0 0.0 0.8377" xyz="0.13676 0.27111 0.280"/>
    <axis xyz="0 0 1"/>
    <parent link="base_link"/>
    <child link="base_sonar_04_link"/>
  </joint>
  <gazebo reference="base_sonar_04_link">
    <sensor name="base_sonar_04" type="ray">
      <pose>0 0 0 0 0 0</pose>
      <update_rate>5</update_rate>
      <visualize>false</visualize>
      <ray>
        <scan>
          <horizontal>
            <samples>5</samples>
            <resolution>1</resolution>
            <min_angle>-0.25</min_angle>
            <max_angle>0.25</max_angle>
          </horizontal>
          <vertical>
            <samples>5</samples>
            <resolution>1</resolution>
            <min_angle>-0.25</min_angle>
            <max_angle>0.25</max_angle>
          </vertical>
        </scan>
        <range>
          <min>0.01</min>
          <max>0.75</max>
          <resolution>0.01</resolution>
        </range>
      </ray>
      <plugin filename="libgazebo_ros_range.so" name="gazebo_ros_range">
        <gaussianNoise>0.005</gaussianNoise>
        <alwaysOn>true</alwaysOn>
        <updateRate>5</updateRate>
        <topicName>sonar_base</topicName>
        <frameName>base_sonar_04_link</frameName>
        <fov>0.5</fov>
        <radiation>ultrasound</radiation>
      </plugin>
    </sensor>
  </gazebo>
  <link name="base_sonar_12_link">
    <inertial>
      <mass value="0.001"/>
      <origin rpy="0 0 0" xyz="0 0 0"/>
      <inertia ixx="0.0001" ixy="0" ixz="0" iyy="0.000001" iyz="0" izz="0.0001"/>
    </inertial>
  </link>
  <joint name="base_sonar_12_joint" type="fixed">
    <origin rpy="0.0 0.0 -0.8377" xyz="0.13676 -0.27111 0.280"/>
    <axis xyz="0 0 1"/>
    <parent link="base_link"/>
    <child link="base_sonar_12_link"/>
  </joint>
  <gazebo reference="base_sonar_12_link">
    <sensor name="base_sonar_12" type="ray">
      <pose>0 0 0 0 0 0</pose>
      <update_rate>5</update_rate>
      <visualize>false</visualize>
      <ray>
        <scan>
          <horizontal>
            <samples>5</samples>
            <resolution>1</resolution>
            <min_angle>-0.25</min_angle>
            <max_angle>0.25</max_angle>
          </horizontal>
          <vertical>
            <samples>5</samples>
            <resolution>1</resolution>
            <min_angle>-0.25</min_angle>
            <max_angle>0.25</max_angle>
          </vertical>
        </scan>
        <range>
          <min>0.01</min>
          <max>0.75</max>
          <resolution>0.01</resolution>
        </range>
      </ray>
      <plugin filename="libgazebo_ros_range.so" name="gazebo_ros_range">
        <gaussianNoise>0.005</gaussianNoise>
        <alwaysOn>true</alwaysOn>
        <updateRate>5</updateRate>
        <topicName>sonar_base</topicName>
        <frameName>base_sonar_12_link</frameName>
        <fov>0.5</fov>
        <radiation>ultrasound</radiation>
      </plugin>
    </sensor>
  </gazebo>
  <link name="base_sonar_05_link">
    <inertial>
      <mass value="0.001"/>
      <origin rpy="0 0 0" xyz="0 0 0"/>
      <inertia ixx="0.0001" ixy="0" ixz="0" iyy="0.000001" iyz="0" izz="0.0001"/>
    </inertial>
  </link>
  <joint name="base_sonar_05_joint" type="fixed">
    <origin rpy="0.0 0.0 1.5708" xyz="-0.14 0.33455 0.27"/>
    <axis xyz="0 0 1"/>
    <parent link="base_link"/>
    <child link="base_sonar_05_link"/>
  </joint>
  <gazebo reference="base_sonar_05_link">
    <sensor name="base_sonar_05" type="ray">
      <pose>0 0 0 0 0 0</pose>
      <update_rate>5</update_rate>
      <visualize>false</visualize>
      <ray>
        <scan>
          <horizontal>
            <samples>5</samples>
            <resolution>1</resolution>
            <min_angle>-0.25</min_angle>
            <max_angle>0.25</max_angle>
          </horizontal>
          <vertical>
            <samples>5</samples>
            <resolution>1</resolution>
            <min_angle>-0.25</min_angle>
            <max_angle>0.25</max_angle>
          </vertical>
        </scan>
        <range>
          <min>0.01</min>
          <max>0.5</max>
          <resolution>0.01</resolution>
        </range>
      </ray>
      <plugin filename="libgazebo_ros_range.so" name="gazebo_ros_range">
        <gaussianNoise>0.005</gaussianNoise>
        <alwaysOn>true</alwaysOn>
        <updateRate>5</updateRate>
        <topicName>sonar_base</topicName>
        <frameName>base_sonar_05_link</frameName>
        <fov>0.5</fov>
        <radiation>ultrasound</radiation>
      </plugin>
    </sensor>
  </gazebo>
  <link name="base_sonar_11_link">
    <inertial>
      <mass value="0.001"/>
      <origin rpy="0 0 0" xyz="0 0 0"/>
      <inertia ixx="0.0001" ixy="0" ixz="0" iyy="0.000001" iyz="0" izz="0.0001"/>
    </inertial>
  </link>
  <joint name="base_sonar_11_joint" type="fixed">
    <origin rpy="0.0 0.0 -1.5708" xyz="-0.14 -0.33455 0.27"/>
    <axis xyz="0 0 1"/>
    <parent link="base_link"/>
    <child link="base_sonar_11_link"/>
  </joint>
  <gazebo reference="base_sonar_11_link">
    <sensor name="base_sonar_11" type="ray">
      <pose>0 0 0 0 0 0</pose>
      <update_rate>5</update_rate>
      <visualize>false</visualize>
      <ray>
        <scan>
          <horizontal>
            <samples>5</samples>
            <resolution>1</resolution>
            <min_angle>-0.25</min_angle>
            <max_angle>0.25</max_angle>
          </horizontal>
          <vertical>
            <samples>5</samples>
            <resolution>1</resolution>
            <min_angle>-0.25</min_angle>
            <max_angle>0.25</max_angle>
          </vertical>
        </scan>
        <range>
          <min>0.01</min>
          <max>0.5</max>
          <resolution>0.01</resolution>
        </range>
      </ray>
      <plugin filename="libgazebo_ros_range.so" name="gazebo_ros_range">
        <gaussianNoise>0.005</gaussianNoise>
        <alwaysOn>true</alwaysOn>
        <updateRate>5</updateRate>
        <topicName>sonar_base</topicName>
        <frameName>base_sonar_11_link</frameName>
        <fov>0.5</fov>
        <radiation>ultrasound</radiation>
      </plugin>
    </sensor>
  </gazebo>
  <link name="base_sonar_06_link">
    <inertial>
      <mass value="0.001"/>
      <origin rpy="0 0 0" xyz="0 0 0"/>
      <inertia ixx="0.0001" ixy="0" ixz="0" iyy="0.000001" iyz="0" izz="0.0001"/>
    </inertial>
  </link>
  <joint name="base_sonar_06_joint" type="fixed">
    <origin rpy="0.0 0.0 1.9547" xyz="-0.35563 0.28266 0.25"/>
    <axis xyz="0 0 1"/>
    <parent link="base_link"/>
    <child link="base_sonar_06_link"/>
  </joint>
  <gazebo reference="base_sonar_06_link">
    <sensor name="base_sonar_06" type="ray">
      <pose>0 0 0 0 0 0</pose>
      <update_rate>5</update_rate>
      <visualize>false</visualize>
      <ray>
        <scan>
          <horizontal>
            <samples>5</samples>
            <resolution>1</resolution>
            <min_angle>-0.25</min_angle>
            <max_angle>0.25</max_angle>
          </horizontal>
          <vertical>
            <samples>5</samples>
            <resolution>1</resolution>
            <min_angle>-0.25</min_angle>
            <max_angle>0.25</max_angle>
          </vertical>
        </scan>
        <range>
          <min>0.005</min>
          <max>0.5</max>
          <resolution>0.01</resolution>
        </range>
      </ray>
      <plugin filename="libgazebo_ros_range.so" name="gazebo_ros_range">
        <gaussianNoise>0.005</gaussianNoise>
        <alwaysOn>true</alwaysOn>
        <updateRate>5</updateRate>
        <topicName>sonar_base</topicName>
        <frameName>base_sonar_06_link</frameName>
        <fov>0.5</fov>
        <radiation>ultrasound</radiation>
      </plugin>
    </sensor>
  </gazebo>
  <link name="base_sonar_10_link">
    <inertial>
      <mass value="0.001"/>
      <origin rpy="0 0 0" xyz="0 0 0"/>
      <inertia ixx="0.0001" ixy="0" ixz="0" iyy="0.000001" iyz="0" izz="0.0001"/>
    </inertial>
  </link>
  <joint name="base_sonar_10_joint" type="fixed">
    <origin rpy="0.0 0.0 -1.9547" xyz="-0.35563 -0.28266 0.25"/>
    <axis xyz="0 0 1"/>
    <parent link="base_link"/>
    <child link="base_sonar_10_link"/>
  </joint>
  <gazebo reference="base_sonar_10_link">
    <sensor name="base_sonar_10" type="ray">
      <pose>0 0 0 0 0 0</pose>
      <update_rate>5</update_rate>
      <visualize>false</visualize>
      <ray>
        <scan>
          <horizontal>
            <samples>5</samples>
            <resolution>1</resolution>
            <min_angle>-0.25</min_angle>
            <max_angle>0.25</max_angle>
          </horizontal>
          <vertical>
            <samples>5</samples>
            <resolution>1</resolution>
            <min_angle>-0.25</min_angle>
            <max_angle>0.25</max_angle>
          </vertical>
        </scan>
        <range>
          <min>0.005</min>
          <max>0.5</max>
          <resolution>0.01</resolution>
        </range>
      </ray>
      <plugin filename="libgazebo_ros_range.so" name="gazebo_ros_range">
        <gaussianNoise>0.005</gaussianNoise>
        <alwaysOn>true</alwaysOn>
        <updateRate>5</updateRate>
        <topicName>sonar_base</topicName>
        <frameName>base_sonar_10_link</frameName>
        <fov>0.5</fov>
        <radiation>ultrasound</radiation>
      </plugin>
    </sensor>
  </gazebo>
  <link name="base_sonar_07_link">
    <inertial>
      <mass value="0.001"/>
      <origin rpy="0 0 0" xyz="0 0 0"/>
      <inertia ixx="0.0001" ixy="0" ixz="0" iyy="0.000001" iyz="0" izz="0.0001"/>
    </inertial>
  </link>
  <joint name="base_sonar_07_joint" type="fixed">
    <origin rpy="0.0 0.0 2.6354" xyz="-0.48412 0.15127 0.29"/>
    <axis xyz="0 0 1"/>
    <parent link="base_link"/>
    <child link="base_sonar_07_link"/>
  </joint>
  <gazebo reference="base_sonar_07_link">
    <sensor name="base_sonar_07" type="ray">
      <pose>0 0 0 0 0 0</pose>
      <update_rate>5</update_rate>
      <visualize>false</visualize>
      <ray>
        <scan>
          <horizontal>
            <samples>5</samples>
            <resolution>1</resolution>
            <min_angle>-0.25</min_angle>
            <max_angle>0.25</max_angle>
          </horizontal>
          <vertical>
            <samples>5</samples>
            <resolution>1</resolution>
            <min_angle>-0.25</min_angle>
            <max_angle>0.25</max_angle>
          </vertical>
        </scan>
        <range>
          <min>0.01</min>
          <max>0.7</max>
          <resolution>0.01</resolution>
        </range>
      </ray>
      <plugin filename="libgazebo_ros_range.so" name="gazebo_ros_range">
        <gaussianNoise>0.005</gaussianNoise>
        <alwaysOn>true</alwaysOn>
        <updateRate>5</updateRate>
        <topicName>sonar_base</topicName>
        <frameName>base_sonar_07_link</frameName>
        <fov>0.5</fov>
        <radiation>ultrasound</radiation>
      </plugin>
    </sensor>
  </gazebo>
  <link name="base_sonar_09_link">
    <inertial>
      <mass value="0.001"/>
      <origin rpy="0 0 0" xyz="0 0 0"/>
      <inertia ixx="0.0001" ixy="0" ixz="0" iyy="0.000001" iyz="0" izz="0.0001"/>
    </inertial>
  </link>
  <joint name="base_sonar_09_joint" type="fixed">
    <origin rpy="0.0 0.0 -2.6354" xyz="-0.48412 -0.15127 0.29"/>
    <axis xyz="0 0 1"/>
    <parent link="base_link"/>
    <child link="base_sonar_09_link"/>
  </joint>
  <gazebo reference="base_sonar_09_link">
    <sensor name="base_sonar_09" type="ray">
      <pose>0 0 0 0 0 0</pose>
      <update_rate>5</update_rate>
      <visualize>false</visualize>
      <ray>
        <scan>
          <horizontal>
            <samples>5</samples>
            <resolution>1</resolution>
            <min_angle>-0.25</min_angle>
            <max_angle>0.25</max_angle>
          </horizontal>
          <vertical>
            <samples>5</samples>
            <resolution>1</resolution>
            <min_angle>-0.25</min_angle>
            <max_angle>0.25</max_angle>
          </vertical>
        </scan>
        <range>
          <min>0.01</min>
          <max>0.7</max>
          <resolution>0.01</resolution>
        </range>
      </ray>
      <plugin filename="libgazebo_ros_range.so" name="gazebo_ros_range">
        <gaussianNoise>0.005</gaussianNoise>
        <alwaysOn>true</alwaysOn>
        <updateRate>5</updateRate>
        <topicName>sonar_base</topicName>
        <frameName>base_sonar_09_link</frameName>
        <fov>0.5</fov>
        <radiation>ultrasound</radiation>
      </plugin>
    </sensor>
  </gazebo>
  <link name="base_sonar_08_link">
    <inertial>
      <mass value="0.001"/>
      <origin rpy="0 0 0" xyz="0 0 0"/>
      <inertia ixx="0.0001" ixy="0" ixz="0" iyy="0.000001" iyz="0" izz="0.0001"/>
    </inertial>
  </link>
  <joint name="base_sonar_08_joint" type="fixed">
    <origin rpy="0.0 0.0 -3.1415" xyz="-0.51188 0.0 0.26"/>
    <axis xyz="0 0 1"/>
    <parent link="base_link"/>
    <child link="base_sonar_08_link"/>
  </joint>
  <gazebo reference="base_sonar_08_link">
    <sensor name="base_sonar_08" type="ray">
      <pose>0 0 0 0 0 0</pose>
      <update_rate>5</update_rate>
      <visualize>false</visualize>
      <ray>
        <scan>
          <horizontal>
            <samples>5</samples>
            <resolution>1</resolution>
            <min_angle>-0.25</min_angle>
            <max_angle>0.25</max_angle>
          </horizontal>
          <vertical>
            <samples>5</samples>
            <resolution>1</resolution>
            <min_angle>-0.25</min_angle>
            <max_angle>0.25</max_angle>
          </vertical>
        </scan>
        <range>
          <min>0.01</min>
          <max>0.7</max>
          <resolution>0.01</resolution>
        </range>
      </ray>
      <plugin filename="libgazebo_ros_range.so" name="gazebo_ros_range">
        <gaussianNoise>0.005</gaussianNoise>
        <alwaysOn>true</alwaysOn>
        <updateRate>5</updateRate>
        <topicName>sonar_base</topicName>
        <frameName>base_sonar_08_link</frameName>
        <fov>0.5</fov>
        <radiation>ultrasound</radiation>
      </plugin>
    </sensor>
  </gazebo>
  <link name="base_ir_01_link">
    <inertial>
      <mass value="0.001"/>
      <origin rpy="0 0 0" xyz="0 0 0"/>
      <inertia ixx="0.0001" ixy="0" ixz="0" iyy="0.000001" iyz="0" izz="0.0001"/>
    </inertial>
  </link>
  <joint name="base_ir_01_joint" type="fixed">
    <origin rpy="0.0 -0.8726 0.0" xyz="0.1804 -0.12463 0.22"/>
    <axis xyz="0 0 1"/>
    <parent link="base_link"/>
    <child link="base_ir_01_link"/>
  </joint>
  <gazebo reference="base_ir_01_link">
    <sensor name="base_ir_01" type="ray">
      <pose>0 0 0 0 0 0</pose>
      <update_rate>10</update_rate>
      <visualize>false</visualize>
      <ray>
        <scan>
          <horizontal>
            <samples>5</samples>
            <resolution>1</resolution>
            <min_angle>-0.05</min_angle>
            <max_angle>0.05</max_angle>
          </horizontal>
          <vertical>
            <samples>5</samples>
            <resolution>1</resolution>
            <min_angle>-0.05</min_angle>
            <max_angle>0.05</max_angle>
          </vertical>
        </scan>
        <range>
          <min>0.01</min>
          <max>1.45</max>
          <resolution>0.01</resolution>
        </range>
      </ray>
      <plugin filename="libgazebo_ros_range.so" name="gazebo_ros_range">
        <gaussianNoise>0.005</gaussianNoise>
        <alwaysOn>true</alwaysOn>
        <updateRate>10</updateRate>
        <topicName>ir_base</topicName>
        <frameName>base_ir_01_link</frameName>
        <fov>0.1</fov>
        <radiation>infrared</radiation>
      </plugin>
    </sensor>
  </gazebo>
  <link name="base_ir_02_link">
    <inertial>
      <mass value="0.001"/>
      <origin rpy="0 0 0" xyz="0 0 0"/>
      <inertia ixx="0.0001" ixy="0" ixz="0" iyy="0.000001" iyz="0" izz="0.0001"/>
    </inertial>
  </link>
  <joint name="base_ir_02_joint" type="fixed">
    <origin rpy="0.0 -0.8726 0.0" xyz="0.18574 0.0 0.22"/>
    <axis xyz="0 0 1"/>
    <parent link="base_link"/>
    <child link="base_ir_02_link"/>
  </joint>
  <gazebo reference="base_ir_02_link">
    <sensor name="base_ir_02" type="ray">
      <pose>0 0 0 0 0 0</pose>
      <update_rate>10</update_rate>
      <visualize>false</visualize>
      <ray>
        <scan>
          <horizontal>
            <samples>5</samples>
            <resolution>1</resolution>
            <min_angle>-0.05</min_angle>
            <max_angle>0.05</max_angle>
          </horizontal>
          <vertical>
            <samples>5</samples>
            <resolution>1</resolution>
            <min_angle>-0.05</min_angle>
            <max_angle>0.05</max_angle>
          </vertical>
        </scan>
        <range>
          <min>0.01</min>
          <max>1.45</max>
          <resolution>0.01</resolution>
        </range>
      </ray>
      <plugin filename="libgazebo_ros_range.so" name="gazebo_ros_range">
        <gaussianNoise>0.005</gaussianNoise>
        <alwaysOn>true</alwaysOn>
        <updateRate>10</updateRate>
        <topicName>ir_base</topicName>
        <frameName>base_ir_02_link</frameName>
        <fov>0.1</fov>
        <radiation>infrared</radiation>
      </plugin>
    </sensor>
  </gazebo>
  <link name="base_ir_03_link">
    <inertial>
      <mass value="0.001"/>
      <origin rpy="0 0 0" xyz="0 0 0"/>
      <inertia ixx="0.0001" ixy="0" ixz="0" iyy="0.000001" iyz="0" izz="0.0001"/>
    </inertial>
  </link>
  <joint name="base_ir_03_joint" type="fixed">
    <origin rpy="0.0 -0.8726 0.0" xyz="0.1804 0.12463 0.22"/>
    <axis xyz="0 0 1"/>
    <parent link="base_link"/>
    <child link="base_ir_03_link"/>
  </joint>
  <gazebo reference="base_ir_03_link">
    <sensor name="base_ir_03" type="ray">
      <pose>0 0 0 0 0 0</pose>
      <update_rate>10</update_rate>
      <visualize>false</visualize>
      <ray>
        <scan>
          <horizontal>
            <samples>5</samples>
            <resolution>1</resolution>
            <min_angle>-0.05</min_angle>
            <max_angle>0.05</max_angle>
          </horizontal>
          <vertical>
            <samples>5</samples>
            <resolution>1</resolution>
            <min_angle>-0.05</min_angle>
            <max_angle>0.05</max_angle>
          </vertical>
        </scan>
        <range>
          <min>0.01</min>
          <max>1.45</max>
          <resolution>0.01</resolution>
        </range>
      </ray>
      <plugin filename="libgazebo_ros_range.so" name="gazebo_ros_range">
        <gaussianNoise>0.005</gaussianNoise>
        <alwaysOn>true</alwaysOn>
        <updateRate>10</updateRate>
        <topicName>ir_base</topicName>
        <frameName>base_ir_03_link</frameName>
        <fov>0.1</fov>
        <radiation>infrared</radiation>
      </plugin>
    </sensor>
  </gazebo>
  <xacro:bumper_reem name="base_bumper_01" parent="base" ros_topic="bumper_base" update_rate="25">
    <origin rpy="0 0 -0.261799387799" xyz="0.325 -0.15 0.15"/>
  </xacro:bumper_reem>
  <xacro:bumper_reem name="base_bumper_02" parent="base" ros_topic="bumper_contact" update_rate="25">
    <origin rpy="0 0 0.261799387799" xyz="0.325 0.15 0.15"/>
  </xacro:bumper_reem>
  <xacro:bumper_reem name="base_bumper_03" parent="base" ros_topic="bumper_contact" update_rate="25">
    <origin rpy="0 0 1.57079632679" xyz="-0.04 0.33 0.1"/>
  </xacro:bumper_reem>
  <xacro:bumper_reem name="base_bumper_04" parent="base" ros_topic="bumper_contact" update_rate="25">
    <origin rpy="0 0 1.74532925199" xyz="-0.3 0.31 0.1"/>
  </xacro:bumper_reem>
  <xacro:bumper_reem name="base_bumper_05" parent="base" ros_topic="bumper_contact" update_rate="25">
    <origin rpy="0 0 3.14159265359" xyz="-0.545 0.0 0.1"/>
  </xacro:bumper_reem>
  <xacro:bumper_reem name="base_bumper_06" parent="base" ros_topic="bumper_base" update_rate="25">
    <origin rpy="0 0 -1.74532925199" xyz="-0.3 -0.31 0.1"/>
  </xacro:bumper_reem>
  <xacro:bumper_reem name="base_bumper_07" parent="base" ros_topic="bumper_contact" update_rate="25">
    <origin rpy="0 0 -1.57079632679" xyz="-0.04 -0.33 0.1"/>
  </xacro:bumper_reem>
  <link name="wheel_right_link">
    <inertial>
      <origin rpy="0 0 0" xyz="0 0 0"/>
      <mass value="1.0"/>
      <inertia ixx="1" ixy="0" ixz="0" iyy="1" iyz="0" izz="1"/>
      <!--<origin xyz="0 0 0" rpy="0 0 0" />
        <mass value="3.5" />
        <inertia ixx="0.00156"  ixy="0"  ixz="0" iyy="0.00156" iyz="0" izz="0.0273" />-->
    </inertial>
    <visual>
      <origin rpy="0 0 0" xyz="0 0 0"/>
      <geometry>
        <cylinder length="0.082" radius="0.125"/>
      </geometry>
      <material name="DarkGrey"/>
    </visual>
    <collision>
      <origin rpy="0 0 0" xyz="0 0 0"/>
      <geometry>
        <cylinder length="0.082" radius="0.125"/>
      </geometry>
    </collision>
  </link>
  <joint name="wheel_right_joint" type="continuous">
    <parent link="base_link"/>
    <child link="wheel_right_link"/>
    <origin rpy="-1.57079632679 0 0" xyz="0 -0.246 0.125"/>
    <axis xyz="0 0 1"/>
  </joint>
  <transmission name="wheel_right_trans" type="pr2_mechanism_model/SimpleTransmission">
    <actuator name="wheel_right_motor"/>
    <joint name="wheel_right_joint"/>
    <mechanicalReduction>1.0</mechanicalReduction>
  </transmission>
  <link name="wheel_left_link">
    <inertial>
      <origin rpy="0 0 0" xyz="0 0 0"/>
      <mass value="1.0"/>
      <inertia ixx="1" ixy="0" ixz="0" iyy="1" iyz="0" izz="1"/>
      <!--<origin xyz="0 0 0" rpy="0 0 0" />
        <mass value="3.5" />
        <inertia ixx="0.00156"  ixy="0"  ixz="0" iyy="0.00156" iyz="0" izz="0.0273" />-->
    </inertial>
    <visual>
      <origin rpy="0 0 0" xyz="0 0 0"/>
      <geometry>
        <cylinder length="0.082" radius="0.125"/>
      </geometry>
      <material name="DarkGrey"/>
    </visual>
    <collision>
      <origin rpy="0 0 0" xyz="0 0 0"/>
      <geometry>
        <cylinder length="0.082" radius="0.125"/>
      </geometry>
    </collision>
  </link>
  <joint name="wheel_left_joint" type="continuous">
    <parent link="base_link"/>
    <child link="wheel_left_link"/>
    <origin rpy="-1.57079632679 0 0" xyz="0 0.246 0.125"/>
    <axis xyz="0 0 1"/>
  </joint>
  <transmission name="wheel_left_trans" type="pr2_mechanism_model/SimpleTransmission">
    <actuator name="wheel_left_motor"/>
    <joint name="wheel_left_joint"/>
    <mechanicalReduction>1.0</mechanicalReduction>
  </transmission>
  <link name="caster_right_1_link">
    <inertial>
      <origin rpy="0 0 0" xyz="0 0 0"/>
      <mass value="0.1"/>
      <inertia ixx="0.012411765597" ixy="-0.000711733678" ixz="0.00050272983" iyy="0.015218160428" iyz="-0.000004273467" izz="0.011763977943"/>
      <!--<origin xyz="0 0 0" rpy="0 0 0"/>
        <mass value="0.1" />
        <inertia  ixx="0" ixy="0" ixz="0" iyy="0" iyz="0" izz="0" />-->
    </inertial>
    <visual>
      <origin rpy="0 0 0" xyz="-0.00675 0 0.03125"/>
      <geometry>
        <box size="0.0625 0.0444 0.0625"/>
      </geometry>
      <material name="DarkGrey"/>
    </visual>
    <collision>
      <origin rpy="0 0 0" xyz="-0.00675 0 0.03125"/>
      <geometry>
        <box size="0.0625 0.0444 0.0625"/>
      </geometry>
    </collision>
  </link>
  <link name="caster_right_2_link">
    <inertial>
      <origin rpy="0 0 0" xyz="0 0 0"/>
      <mass value="0.4"/>
      <inertia ixx="0.00044" ixy="0" ixz="0" iyy="0.00044" iyz="0" izz="0.00078"/>
    </inertial>
    <visual>
      <origin rpy="0 0 0" xyz="0 0 0"/>
      <geometry>
        <cylinder length="0.037" radius="0.0625"/>
      </geometry>
      <material name="DarkGrey"/>
    </visual>
    <collision>
      <origin rpy="0 0 0" xyz="0 0 0"/>
      <geometry>
        <cylinder length="0.037" radius="0.0625"/>
      </geometry>
    </collision>
  </link>
  <joint name="caster_right_1_joint" type="continuous">
    <parent link="base_link"/>
    <child link="caster_right_1_link"/>
    <origin rpy="0 0 0" xyz="-0.3805 -0.15 0.0625"/>
    <axis xyz="0 0 1"/>
  </joint>
  <joint name="caster_right_2_joint" type="continuous">
    <parent link="caster_right_1_link"/>
    <child link="caster_right_2_link"/>
    <origin rpy="-1.57079632679 0 0" xyz="-0.038 0 0"/>
    <axis xyz="0 0 1"/>
  </joint>
  <transmission name="caster_right_1_trans" type="pr2_mechanism_model/SimpleTransmission">
    <actuator name="caster_right_1_motor"/>
    <joint name="caster_right_1_joint"/>
    <mechanicalReduction>1</mechanicalReduction>
  </transmission>
  <transmission name="caster_right_2_trans" type="pr2_mechanism_model/SimpleTransmission">
    <actuator name="caster_right_2_motor"/>
    <joint name="caster_right_2_joint"/>
    <mechanicalReduction>1</mechanicalReduction>
  </transmission>
  <link name="caster_left_1_link">
    <inertial>
      <origin rpy="0 0 0" xyz="0 0 0"/>
      <mass value="0.1"/>
      <inertia ixx="0.012411765597" ixy="-0.000711733678" ixz="0.00050272983" iyy="0.015218160428" iyz="-0.000004273467" izz="0.011763977943"/>
      <!--<origin xyz="0 0 0" rpy="0 0 0"/>
        <mass value="0.1" />
        <inertia  ixx="0" ixy="0" ixz="0" iyy="0" iyz="0" izz="0" />-->
    </inertial>
    <visual>
      <origin rpy="0 0 0" xyz="-0.00675 0 0.03125"/>
      <geometry>
        <box size="0.0625 0.0444 0.0625"/>
      </geometry>
      <material name="DarkGrey"/>
    </visual>
    <collision>
      <origin rpy="0 0 0" xyz="-0.00675 0 0.03125"/>
      <geometry>
        <box size="0.0625 0.0444 0.0625"/>
      </geometry>
    </collision>
  </link>
  <link name="caster_left_2_link">
    <inertial>
      <origin rpy="0 0 0" xyz="0 0 0"/>
      <mass value="0.4"/>
      <inertia ixx="0.00044" ixy="0" ixz="0" iyy="0.00044" iyz="0" izz="0.00078"/>
    </inertial>
    <visual>
      <origin rpy="0 0 0" xyz="0 0 0"/>
      <geometry>
        <cylinder length="0.037" radius="0.0625"/>
      </geometry>
      <material name="DarkGrey"/>
    </visual>
    <collision>
      <origin rpy="0 0 0" xyz="0 0 0"/>
      <geometry>
        <cylinder length="0.037" radius="0.0625"/>
      </geometry>
    </collision>
  </link>
  <joint name="caster_left_1_joint" type="continuous">
    <parent link="base_link"/>
    <child link="caster_left_1_link"/>
    <origin rpy="0 0 0" xyz="-0.3805 0.15 0.0625"/>
    <axis xyz="0 0 1"/>
  </joint>
  <joint name="caster_left_2_joint" type="continuous">
    <parent link="caster_left_1_link"/>
    <child link="caster_left_2_link"/>
    <origin rpy="-1.57079632679 0 0" xyz="-0.038 0 0"/>
    <axis xyz="0 0 1"/>
  </joint>
  <transmission name="caster_left_1_trans" type="pr2_mechanism_model/SimpleTransmission">
    <actuator name="caster_left_1_motor"/>
    <joint name="caster_left_1_joint"/>
    <mechanicalReduction>1</mechanicalReduction>
  </transmission>
  <transmission name="caster_left_2_trans" type="pr2_mechanism_model/SimpleTransmission">
    <actuator name="caster_left_2_motor"/>
    <joint name="caster_left_2_joint"/>
    <mechanicalReduction>1</mechanicalReduction>
  </transmission>
  <gazebo>
    <plugin filename="libgazebo_pal_ros_diffdrive.so" name="pal_gazebo_diff_drive">
      <left_joint>wheel_left_joint</left_joint>
      <right_joint>wheel_right_joint</right_joint>
      <torque>15</torque>
    </plugin>
  </gazebo>
  <link name="base_cargo_link">
    <inertial>
      <mass value="1.0"/>
      <origin xyz="0 0 0"/>
      <inertia ixx="0.01" ixy="0.0" ixz="0.0" iyy="0.01" iyz="0.0" izz="0.01"/>
      <!--<mass value="1.0" />
        <origin xyz="0 0 -0.5" />
        <inertia ixx="0.0" ixy="0.0" ixz="0.0" iyy="0.0" iyz="0.0" izz="0.0" />-->
    </inertial>
    <visual>
      <origin rpy="0 0 0" xyz="0 0 -0.5"/>
      <geometry>
        <box size="0.001 0.001 0.001"/>
      </geometry>
      <material name="Green"/>
    </visual>
    <collision>
      <origin rpy="0 0 0" xyz="0.05 0 0.02"/>
      <geometry>
        <box size="0.30 0.40 0.25"/>
        <!-- Generous hand luggage size allowed in an airplane is 0.55x0.45x0.25. This slightly smaller. -->
      </geometry>
    </collision>
  </link>
  <joint name="base_cargo_link" type="fixed">
    <origin rpy="0 0.18 0" xyz="-0.41 0 0.605"/>
    <child link="base_cargo_link"/>
    <parent link="base_link"/>
  </joint>
  <link name="torso_1_link">
    <inertial>
      <origin rpy="0 0 0" xyz="-0.00476 0.00413 0.13972"/>
      <mass value="9.807"/>
      <!-- NOTE: Assuming cylinder with r=0.15, h=0.14 -->
      <inertia ixx="0.015591" ixy="0" ixz="0" iyy="0.015591" iyz="0" izz="0.024165"/>
    </inertial>
    <visual>
      <geometry>
        <mesh filename="package://reem_description/meshes/torso/torso_1.dae"/>
      </geometry>
      <material name="DarkGrey"/>
    </visual>
    <collision>
      <geometry>
        <mesh filename="package://reem_description/meshes/torso/torso_1_collision.stl"/>
      </geometry>
    </collision>
  </link>
  <joint name="torso_1_joint" type="revolute">
    <parent link="base_link"/>
    <child link="torso_1_link"/>
    <origin rpy="0 0 0" xyz="-0.108 0 0.8725"/>
    <axis xyz="0 0 1"/>
    <limit effort="30" lower="-1.308996939" upper="1.308996939" velocity="1.0"/>
    <dynamics damping="5.0" friction="1.0"/>
  </joint>
  <transmission name="torso_1_trans" type="pr2_mechanism_model/SimpleTransmission">
    <actuator name="torso_1_motor"/>
    <joint name="torso_1_joint"/>
    <mechanicalReduction>200</mechanicalReduction>
  </transmission>
  <link name="torso_2_link">
    <inertial>
      <origin rpy="0 0 0" xyz="0.00675 -0.16711 0.00016"/>
      <mass value="13.299"/>
      <!-- NOTE: Assuming box with d=0.2, w=0.4, h=0.46 -->
      <inertia ixx="0.41183" ixy="0" ixz="0" iyy="0.22165" iyz="0" izz="0.27884"/>
    </inertial>
    <visual>
      <geometry>
        <mesh filename="package://reem_description/meshes/torso/torso_2.dae"/>
      </geometry>
      <material name="LightGrey"/>
    </visual>
    <collision>
      <geometry>
        <mesh filename="package://reem_description/meshes/torso/torso_2_collision.stl"/>
      </geometry>
    </collision>
  </link>
  <joint name="torso_2_joint" type="revolute">
    <parent link="torso_1_link"/>
    <child link="torso_2_link"/>
    <origin rpy="-1.57079632679 0 0" xyz="-0 0 0.1985"/>
    <axis xyz="0 0 1"/>
    <limit effort="80" lower="-0.261799387799" upper="0.698131700798" velocity="1.0"/>
    <dynamics damping="10.0" friction="1.0"/>
    <!--NOTE: Joint can do 46.2, but set to higher value because of unmodeled springs-->
  </joint>
  <link name="torso_sonar_14_link">
    <inertial>
      <mass value="0.001"/>
      <origin rpy="0 0 0" xyz="0 0 0"/>
      <inertia ixx="0.0001" ixy="0" ixz="0" iyy="0.000001" iyz="0" izz="0.0001"/>
    </inertial>
  </link>
  <joint name="torso_sonar_14_joint" type="fixed">
    <origin rpy="0.0 0.0 0.0" xyz="0.185 -0.029 0.075"/>
    <axis xyz="0 0 1"/>
    <parent link="torso_2_link"/>
    <child link="torso_sonar_14_link"/>
  </joint>
  <gazebo reference="torso_sonar_14_link">
    <sensor name="torso_sonar_14" type="ray">
      <pose>0 0 0 0 0 0</pose>
      <update_rate>5</update_rate>
      <visualize>false</visualize>
      <ray>
        <scan>
          <horizontal>
            <samples>5</samples>
            <resolution>1</resolution>
            <min_angle>-0.17455</min_angle>
            <max_angle>0.17455</max_angle>
          </horizontal>
          <vertical>
            <samples>5</samples>
            <resolution>1</resolution>
            <min_angle>-0.17455</min_angle>
            <max_angle>0.17455</max_angle>
          </vertical>
        </scan>
        <range>
          <min>0.01</min>
          <max>0.7</max>
          <resolution>0.01</resolution>
        </range>
      </ray>
      <plugin filename="libgazebo_ros_range.so" name="gazebo_ros_range">
        <gaussianNoise>0.005</gaussianNoise>
        <alwaysOn>true</alwaysOn>
        <updateRate>5</updateRate>
        <topicName>sonar_torso</topicName>
        <frameName>torso_sonar_14_link</frameName>
        <fov>0.3491</fov>
        <radiation>ultrasound</radiation>
      </plugin>
    </sensor>
  </gazebo>
  <link name="torso_sonar_15_link">
    <inertial>
      <mass value="0.001"/>
      <origin rpy="0 0 0" xyz="0 0 0"/>
      <inertia ixx="0.0001" ixy="0" ixz="0" iyy="0.000001" iyz="0" izz="0.0001"/>
    </inertial>
  </link>
  <joint name="torso_sonar_15_joint" type="fixed">
    <origin rpy="0.0 0.0 0.0" xyz="0.185 -0.029 -0.075"/>
    <axis xyz="0 0 1"/>
    <parent link="torso_2_link"/>
    <child link="torso_sonar_15_link"/>
  </joint>
  <gazebo reference="torso_sonar_15_link">
    <sensor name="torso_sonar_15" type="ray">
      <pose>0 0 0 0 0 0</pose>
      <update_rate>5</update_rate>
      <visualize>false</visualize>
      <ray>
        <scan>
          <horizontal>
            <samples>5</samples>
            <resolution>1</resolution>
            <min_angle>-0.17455</min_angle>
            <max_angle>0.17455</max_angle>
          </horizontal>
          <vertical>
            <samples>5</samples>
            <resolution>1</resolution>
            <min_angle>-0.17455</min_angle>
            <max_angle>0.17455</max_angle>
          </vertical>
        </scan>
        <range>
          <min>0.01</min>
          <max>0.7</max>
          <resolution>0.01</resolution>
        </range>
      </ray>
      <plugin filename="libgazebo_ros_range.so" name="gazebo_ros_range">
        <gaussianNoise>0.005</gaussianNoise>
        <alwaysOn>true</alwaysOn>
        <updateRate>5</updateRate>
        <topicName>sonar_torso</topicName>
        <frameName>torso_sonar_15_link</frameName>
        <fov>0.3491</fov>
        <radiation>ultrasound</radiation>
      </plugin>
    </sensor>
  </gazebo>
  <link name="torso_sonar_13_link">
    <inertial>
      <mass value="0.001"/>
      <origin rpy="0 0 0" xyz="0 0 0"/>
      <inertia ixx="0.0001" ixy="0" ixz="0" iyy="0.000001" iyz="0" izz="0.0001"/>
    </inertial>
  </link>
  <joint name="torso_sonar_13_joint" type="fixed">
    <origin rpy="0.0 3.14159265359 0.0" xyz="-0.2 -0.149 0.0"/>
    <axis xyz="0 0 1"/>
    <parent link="torso_2_link"/>
    <child link="torso_sonar_13_link"/>
  </joint>
  <gazebo reference="torso_sonar_13_link">
    <sensor name="torso_sonar_13" type="ray">
      <pose>0 0 0 0 0 0</pose>
      <update_rate>5</update_rate>
      <visualize>false</visualize>
      <ray>
        <scan>
          <horizontal>
            <samples>5</samples>
            <resolution>1</resolution>
            <min_angle>-0.17455</min_angle>
            <max_angle>0.17455</max_angle>
          </horizontal>
          <vertical>
            <samples>5</samples>
            <resolution>1</resolution>
            <min_angle>-0.17455</min_angle>
            <max_angle>0.17455</max_angle>
          </vertical>
        </scan>
        <range>
          <min>0.01</min>
          <max>0.7</max>
          <resolution>0.01</resolution>
        </range>
      </ray>
      <plugin filename="libgazebo_ros_range.so" name="gazebo_ros_range">
        <gaussianNoise>0.005</gaussianNoise>
        <alwaysOn>true</alwaysOn>
        <updateRate>5</updateRate>
        <topicName>sonar_torso</topicName>
        <frameName>torso_sonar_13_link</frameName>
        <fov>0.3491</fov>
        <radiation>ultrasound</radiation>
      </plugin>
    </sensor>
  </gazebo>
  <transmission name="torso_2_trans" type="pr2_mechanism_model/SimpleTransmission">
    <actuator name="torso_2_motor"/>
    <joint name="torso_2_joint"/>
    <mechanicalReduction>250</mechanicalReduction>
  </transmission>
  <link name="head_1_link">
    <inertial>
      <origin rpy="0 0 0" xyz="0.01741 0.00466 -0.00434"/>
      <mass value="0.98547"/>
      <!-- NOTE: Assuming cylinder with r=0.06, h=0.08 -->
      <!--         <inertia ixx="0.0014125"  ixy="0"  ixz="0" iyy="0.0014125" iyz="0" izz="0.0017738" /> -->
      <inertia ixx="0" ixy="0" ixz="0" iyy="0" iyz="0" izz="0"/>
    </inertial>
    <visual>
      <origin rpy="0 0 0" xyz="0 0 0"/>
      <geometry>
        <mesh filename="package://reem_description/meshes/head/head_1.dae"/>
      </geometry>
      <material name="DarkGrey"/>
    </visual>
    <collision>
      <origin rpy="0 0 0" xyz="0 0 0"/>
      <geometry>
        <mesh filename="package://reem_description/meshes/head/head_1_collision.stl"/>
      </geometry>
    </collision>
  </link>
  <joint name="head_1_joint" type="revolute">
    <parent link="torso_2_link"/>
    <child link="head_1_link"/>
    <origin rpy="1.57079632679 0 0" xyz="-0.024 -0.412 0"/>
    <axis xyz="0 0 1"/>
    <limit effort="3.4" lower="-1.308996939" upper="1.308996939" velocity="1.0"/>
    <dynamics damping="0.5" friction="1.0"/>
  </joint>
  <transmission name="head_1_trans" type="pr2_mechanism_model/SimpleTransmission">
    <actuator name="head_1_motor"/>
    <joint name="head_1_joint"/>
    <mechanicalReduction>144</mechanicalReduction>
  </transmission>
  <link name="head_2_link">
    <inertial>
      <origin rpy="0 0 0" xyz="-0.04431 -0.13008 0.00011"/>
      <mass value="1.20862"/>
      <!-- NOTE: Assuming box with d=0.28433, w=0.20302, h=0.26741 -->
      <!--         <inertia ixx="0.011353"  ixy="0"  ixz="0" iyy="0.012294" iyz="0" izz="0.015345" /> -->
      <!--NOTE: Low (0.1 or lower) diagonal inertia values make Gazebo 1.0.2 simulation unstable when head sensors are added.-->
      <inertia ixx="0.25" ixy="0" ixz="0" iyy="0.25" iyz="0" izz="0.25"/>
    </inertial>
    <visual>
      <origin rpy="0 0 0" xyz="0 0 0"/>
      <geometry>
        <mesh filename="package://reem_description/meshes/head/head_2.dae"/>
      </geometry>
      <material name="LightGrey"/>
    </visual>
    <collision>
      <origin rpy="0 0 0" xyz="0 0 0"/>
      <geometry>
        <mesh filename="package://reem_description/meshes/head/head_2_collision.stl"/>
      </geometry>
    </collision>
  </link>
  <joint name="head_2_joint" type="revolute">
    <parent link="head_1_link"/>
    <child link="head_2_link"/>
    <origin rpy="-1.57079632679 0 0" xyz="0.0445 0 0"/>
    <axis xyz="0 0 1"/>
    <limit effort="3.26" lower="-0.261799387799" upper="0.523598775598" velocity="1.0"/>
    <dynamics damping="0.5" friction="1.0"/>
  </joint>
  <link name="base_sonar_16_link">
    <inertial>
      <mass value="0.001"/>
      <origin rpy="0 0 0" xyz="0 0 0"/>
      <inertia ixx="0.0001" ixy="0" ixz="0" iyy="0.000001" iyz="0" izz="0.0001"/>
    </inertial>
  </link>
  <joint name="base_sonar_16_joint" type="fixed">
    <origin rpy="1.57 0.0 0.0" xyz="0.086 -0.195 0.0"/>
    <axis xyz="0 0 1"/>
    <parent link="head_2_link"/>
    <child link="base_sonar_16_link"/>
  </joint>
  <gazebo reference="base_sonar_16_link">
    <sensor name="base_sonar_16" type="ray">
      <pose>0 0 0 0 0 0</pose>
      <update_rate>5</update_rate>
      <visualize>false</visualize>
      <ray>
        <scan>
          <horizontal>
            <samples>5</samples>
            <resolution>1</resolution>
            <min_angle>-0.17455</min_angle>
            <max_angle>0.17455</max_angle>
          </horizontal>
          <vertical>
            <samples>5</samples>
            <resolution>1</resolution>
            <min_angle>-0.17455</min_angle>
            <max_angle>0.17455</max_angle>
          </vertical>
        </scan>
        <range>
          <min>0.0</min>
          <max>0.6</max>
          <resolution>0.01</resolution>
        </range>
      </ray>
      <plugin filename="libgazebo_ros_range.so" name="gazebo_ros_range">
        <gaussianNoise>0.005</gaussianNoise>
        <alwaysOn>true</alwaysOn>
        <updateRate>5</updateRate>
        <topicName>sonar_torso</topicName>
        <frameName>base_sonar_16_link</frameName>
        <fov>0.3491</fov>
        <radiation>ultrasound</radiation>
      </plugin>
    </sensor>
  </gazebo>
  <transmission name="head_2_trans" type="pr2_mechanism_model/SimpleTransmission">
    <actuator name="head_2_motor"/>
    <joint name="head_2_joint"/>
    <mechanicalReduction>320.32</mechanicalReduction>
  </transmission>
  <!-- The reflect parameter takes the value 1 or -1 to respectively distinguish right from left side in expressions -->
  <link name="arm_right_1_link">
    <inertial>
      <origin rpy="0 0 0" xyz="0.0006 -0.0005 0.20739"/>
      <mass value="2.148"/>
      <inertia ixx="0" ixy="0" ixz="0" iyy="0" iyz="0" izz="0"/>
      <!--         NOTE: Assuming cylinder centered at CoM with r=0.05, h=0.05 with axis parallel to x coordinate -->
      <!--         <inertia ixx="0.0026850"  ixy="0"  ixz="0" iyy="0.0017900" iyz="0" izz="0.0017900" /> -->
    </inertial>
    <visual>
      <origin rpy="0 0 0" xyz="0 0 0"/>
      <geometry>
        <mesh filename="package://reem_description/meshes/arm/arm_1.dae" scale="1 1 -1.0"/>
      </geometry>
      <material name="DarkGrey"/>
    </visual>
    <collision>
      <origin rpy="0 0 0" xyz="0 0 0"/>
      <geometry>
        <mesh filename="package://reem_description/meshes/arm/arm_1_collision.stl" scale="1 1 -1.0"/>
      </geometry>
    </collision>
  </link>
  <joint name="arm_right_1_joint" type="revolute">
    <parent link="torso_2_link"/>
    <child link="arm_right_1_link"/>
    <origin rpy="-2.87979326579 0 0" xyz="-0.015 -0.273 0"/>
    <axis xyz="0 0 1"/>
    <limit effort="39" lower="-0.785398163397" upper="3.14159265359" velocity="1.0"/>
    <dynamics damping="1.5" friction="1.0"/>
  </joint>
  <link name="arm_right_2_link">
    <inertial>
      <origin rpy="0 0 0" xyz="0.0183 -0.09275 0.00478"/>
      <mass value="1.610"/>
      <inertia ixx="0" ixy="0" ixz="0" iyy="0" iyz="0" izz="0"/>
      <!-- NOTE: Assuming cylinder centered at CoM with r=0.05, h=0.05 with axis parallel to y coordinate -->
      <!--         <inertia ixx="0.0013417"  ixy="0"  ixz="0" iyy="0.0020125" iyz="0" izz="0.0013417" /> -->
    </inertial>
    <visual>
      <origin rpy="0 0 0" xyz="0 0 0"/>
      <geometry>
        <mesh filename="package://reem_description/meshes/arm/arm_2.dae" scale="1 1 -1.0"/>
      </geometry>
      <material name="DarkGrey"/>
    </visual>
    <collision>
      <origin rpy="0 0 0" xyz="0 0 0"/>
      <geometry>
        <mesh filename="package://reem_description/meshes/arm/arm_2_collision.stl" scale="1 1 -1.0"/>
      </geometry>
    </collision>
  </link>
  <joint name="arm_right_2_joint" type="revolute">
    <parent link="arm_right_1_link"/>
    <child link="arm_right_2_link"/>
    <origin rpy="-1.57079632679 -1.308996939 1.57079632679" xyz="0 0 0.2385"/>
    <axis xyz="0 0 1"/>
    <limit effort="21.7" lower="-0.261799387799" upper="2.09439510239" velocity="1.0"/>
    <dynamics damping="1.5" friction="1.0"/>
  </joint>
  <link name="arm_right_3_link">
    <inertial>
      <origin rpy="0 0 0" xyz="0.00045 -0.01547 0.07654"/>
      <mass value="1.656"/>
      <inertia ixx="0" ixy="0" ixz="0" iyy="0" iyz="0" izz="0"/>
      <!-- NOTE: Assuming cylinder centered at CoM with r=0.05, h=0.05 with axis parallel to x coordinate -->
      <!--         <inertia ixx="0.0020700"  ixy="0"  ixz="0" iyy="0.0013800" iyz="0" izz="0.0013800" /> -->
    </inertial>
    <visual>
      <origin rpy="0 0 0" xyz="0 0 0"/>
      <geometry>
        <mesh filename="package://reem_description/meshes/arm/arm_3.dae" scale="1 1 -1.0"/>
      </geometry>
      <material name="DarkGrey"/>
    </visual>
    <collision>
      <origin rpy="0 0 0" xyz="0 0 0"/>
      <geometry>
        <mesh filename="package://reem_description/meshes/arm/arm_3_collision.stl" scale="1 1 -1.0"/>
      </geometry>
    </collision>
  </link>
  <joint name="arm_right_3_joint" type="revolute">
    <parent link="arm_right_2_link"/>
    <child link="arm_right_3_link"/>
    <origin rpy="1.57079632679 0 0" xyz="0.02 -0.142 0"/>
    <axis xyz="0 0 1"/>
    <limit effort="17.4" lower="-2.35619449019" upper="2.74889357189" velocity="1.0"/>
    <dynamics damping="1.5" friction="1.0"/>
  </joint>
  <link name="arm_right_4_link">
    <inertial>
      <origin rpy="0 0 0" xyz="-0.06424 0.01712 -0.00666"/>
      <mass value="1.013"/>
      <inertia ixx="0" ixy="0" ixz="0" iyy="0" iyz="0" izz="0"/>
      <!-- NOTE: Assuming cylinder centered at CoM with r=0.05, h=0.05 with axis parallel to x coordinate -->
      <!--         <inertia ixx="0.0012663"  ixy="0"  ixz="0" iyy="0.00084417" iyz="0" izz="0.00084417" /> -->
    </inertial>
    <visual>
      <origin rpy="0 0 0" xyz="0 0 0"/>
      <geometry>
        <mesh filename="package://reem_description/meshes/arm/arm_4.dae" scale="1 1 -1.0"/>
      </geometry>
      <material name="DarkGrey"/>
    </visual>
    <collision>
      <origin rpy="0 0 0" xyz="0 0 0"/>
      <geometry>
        <mesh filename="package://reem_description/meshes/arm/arm_4_collision.stl" scale="1 1 -1.0"/>
      </geometry>
    </collision>
  </link>
  <joint name="arm_right_4_joint" type="revolute">
    <parent link="arm_right_3_link"/>
    <child link="arm_right_4_link"/>
    <origin rpy="0 1.57079632679 0" xyz="0 -0.02 0.088"/>
    <axis xyz="0 0 1"/>
    <limit effort="17.4" lower="0" upper="2.26892802759" velocity="1.0"/>
    <dynamics damping="1.5" friction="1.0"/>
  </joint>
  <link name="arm_right_5_link">
    <inertial>
      <origin rpy="0 0 0" xyz="-0.00045 -0.00009 0.08726"/>
      <mass value="1.858"/>
      <inertia ixx="0" ixy="0" ixz="0" iyy="0" iyz="0" izz="0"/>
      <!-- NOTE: Assuming cylinder centered at CoM with r=0.05, h=0.1 with axis parallel to z coordinate -->
      <!--         <inertia ixx="0.0027096"  ixy="0"  ixz="0" iyy="0.0027096" iyz="0" izz="0.0023225" /> -->
    </inertial>
    <visual>
      <origin rpy="0 0 0" xyz="0 0 0"/>
      <geometry>
        <mesh filename="package://reem_description/meshes/arm/arm_5.dae" scale="1 1 -1.0"/>
      </geometry>
      <material name="LightGrey"/>
    </visual>
    <collision>
      <origin rpy="0 0 0" xyz="0 0 0"/>
      <geometry>
        <mesh filename="package://reem_description/meshes/arm/arm_5_collision.stl" scale="1 1 -1.0"/>
      </geometry>
    </collision>
  </link>
  <joint name="arm_right_5_joint" type="revolute">
    <parent link="arm_right_4_link"/>
    <child link="arm_right_5_link"/>
    <origin rpy="0 -1.57079632679 0" xyz="-0.088 0.02 0"/>
    <axis xyz="0 0 1"/>
    <limit effort="16" lower="-2.09439510239" upper="2.09439510239" velocity="1.0"/>
    <!--TODO: Check effort value!-->
    <dynamics damping="0.5" friction="1.0"/>
  </joint>
  <link name="arm_right_6_link">
    <inertial>
      <origin rpy="0 0 0" xyz="-0.0002 -0.01155 2e-05"/>
      <mass value="0.255"/>
      <inertia ixx="0" ixy="0" ixz="0" iyy="0" iyz="0" izz="0"/>
      <!-- NOTE: Assuming cylinder centered at CoM with r=0.02, h=0.08 with axis parallel to z coordinate -->
      <!--         <inertia ixx="0.0001615"  ixy="0"  ixz="0" iyy="0.0001615" iyz="0" izz="0.000051" /> -->
    </inertial>
    <visual>
      <origin rpy="0 0 0" xyz="0 0 0"/>
      <geometry>
        <mesh filename="package://reem_description/meshes/arm/arm_6.dae" scale="1 1 -1.0"/>
      </geometry>
      <material name="LightGrey"/>
    </visual>
    <collision>
      <origin rpy="0 0 0" xyz="0 0 0"/>
      <geometry>
        <cylinder length="0.0385" radius="0.04"/>
      </geometry>
    </collision>
  </link>
  <joint name="arm_right_6_joint" type="revolute">
    <parent link="arm_right_5_link"/>
    <child link="arm_right_6_link"/>
    <origin rpy="-1.57079632679 0 0" xyz="0 0 0.15"/>
    <axis xyz="0 0 1"/>
    <limit effort="12" lower="-1.57079632679" upper="1.57079632679" velocity="1.0"/>
    <dynamics damping="0.1" friction="1.0"/>
  </joint>
  <link name="arm_right_7_link">
    <inertial>
      <!--TODO: Verify these inertial parameters-->
      <origin rpy="0 0 0" xyz="0 0 0.0547022545"/>
      <mass value="0.152461831"/>
      <inertia ixx="0" ixy="0" ixz="0" iyy="0" iyz="0" izz="0"/>
      <!-- NOTE: Assuming point mass -->
      <!--         <inertia ixx="0"  ixy="0"  ixz="0" iyy="0" iyz="0" izz="0" /> -->
    </inertial>
    <visual>
      <origin rpy="0 0 0" xyz="0 0 0.046"/>
      <geometry>
        <cylinder length="0.005" radius="0.02"/>
      </geometry>
      <material name="DarkGrey"/>
    </visual>
    <collision>
      <origin rpy="0 0 0" xyz="0 0 0.0345"/>
      <geometry>
        <cylinder length="0.023" radius="0.02"/>
      </geometry>
    </collision>
  </link>
  <joint name="arm_right_7_joint" type="revolute">
    <parent link="arm_right_6_link"/>
    <child link="arm_right_7_link"/>
    <origin rpy="1.57079632679 0 0" xyz="0 0 0"/>
    <axis xyz="0 0 1"/>
    <limit effort="12" lower="-2.09439510239" upper="2.09439510239" velocity="1.0"/>
    <dynamics damping="0.1" friction="1.0"/>
  </joint>
  <transmission name="arm_right_5_trans" type="pr2_mechanism_model/SimpleTransmission">
    <actuator name="arm_right_5_motor"/>
    <joint name="arm_right_5_joint"/>
    <mechanicalReduction>336.0</mechanicalReduction>
  </transmission>
  <transmission name="arm_right_6_trans" type="pr2_mechanism_model/SimpleTransmission">
    <actuator name="arm_right_6_motor"/>
    <joint name="arm_right_6_joint"/>
    <mechanicalReduction>336.0</mechanicalReduction>
  </transmission>
  <transmission name="arm_right_7_trans" type="pr2_mechanism_model/SimpleTransmission">
    <actuator name="arm_right_7_motor"/>
    <joint name="arm_right_7_joint"/>
    <mechanicalReduction>336.0</mechanicalReduction>
  </transmission>
  <link name="arm_right_tool_link">
    <inertial>
      <mass value="0.1"/>
      <inertia ixx="0.0" ixy="0.0" ixz="0.0" iyy="0.0" iyz="0.0" izz="0.0"/>
    </inertial>
    <visual>
      <origin rpy="0 1.57079632679 0" xyz="0.001 0 0"/>
      <geometry>
        <cylinder length="0.005" radius="0.005"/>
      </geometry>
      <material name="LightGrey"/>
    </visual>
    <collision>
      <origin rpy="0 1.57079632679 0" xyz="0.001 0 0"/>
      <geometry>
        <cylinder length="0.005" radius="0.005"/>
      </geometry>
    </collision>
  </link>
  <joint name="arm_right_tool_joint" type="fixed">
    <parent link="arm_right_7_link"/>
    <child link="arm_right_tool_link"/>
    <origin rpy="1.57079632679 -1.57079632679 0" xyz="0 0 0.046"/>
  </joint>
  <transmission name="arm_right_1_trans" type="pr2_mechanism_model/SimpleTransmission">
    <actuator name="arm_right_1_motor"/>
    <joint name="arm_right_1_joint"/>
    <mechanicalReduction>100.0</mechanicalReduction>
  </transmission>
  <transmission name="arm_right_2_trans" type="pr2_mechanism_model/SimpleTransmission">
    <actuator name="arm_right_2_motor"/>
    <joint name="arm_right_2_joint"/>
    <mechanicalReduction>100.0</mechanicalReduction>
  </transmission>
  <transmission name="arm_right_3_trans" type="pr2_mechanism_model/SimpleTransmission">
    <actuator name="arm_right_3_motor"/>
    <joint name="arm_right_3_joint"/>
    <mechanicalReduction>80.0</mechanicalReduction>
  </transmission>
  <transmission name="arm_right_4_trans" type="pr2_mechanism_model/SimpleTransmission">
    <actuator name="arm_right_4_motor"/>
    <joint name="arm_right_4_joint"/>
    <mechanicalReduction>80.0</mechanicalReduction>
  </transmission>
  <link name="arm_left_1_link">
    <inertial>
      <origin rpy="0 0 0" xyz="0.0006 -0.0005 -0.20739"/>
      <mass value="2.148"/>
      <inertia ixx="0" ixy="0" ixz="0" iyy="0" iyz="0" izz="0"/>
      <!--         NOTE: Assuming cylinder centered at CoM with r=0.05, h=0.05 with axis parallel to x coordinate -->
      <!--         <inertia ixx="0.0026850"  ixy="0"  ixz="0" iyy="0.0017900" iyz="0" izz="0.0017900" /> -->
    </inertial>
    <visual>
      <origin rpy="0 0 0" xyz="0 0 0"/>
      <geometry>
        <mesh filename="package://reem_description/meshes/arm/arm_1.dae" scale="1 1 1.0"/>
      </geometry>
      <material name="DarkGrey"/>
    </visual>
    <collision>
      <origin rpy="0 0 0" xyz="0 0 0"/>
      <geometry>
        <mesh filename="package://reem_description/meshes/arm/arm_1_collision.stl" scale="1 1 1.0"/>
      </geometry>
    </collision>
  </link>
  <joint name="arm_left_1_joint" type="revolute">
    <parent link="torso_2_link"/>
    <child link="arm_left_1_link"/>
    <origin rpy="2.87979326579 0 0" xyz="-0.015 -0.273 0"/>
    <axis xyz="0 0 1"/>
    <limit effort="39" lower="-0.785398163397" upper="3.14159265359" velocity="1.0"/>
    <dynamics damping="1.5" friction="1.0"/>
  </joint>
  <link name="arm_left_2_link">
    <inertial>
      <origin rpy="0 0 0" xyz="0.0183 -0.09275 -0.00478"/>
      <mass value="1.610"/>
      <inertia ixx="0" ixy="0" ixz="0" iyy="0" iyz="0" izz="0"/>
      <!-- NOTE: Assuming cylinder centered at CoM with r=0.05, h=0.05 with axis parallel to y coordinate -->
      <!--         <inertia ixx="0.0013417"  ixy="0"  ixz="0" iyy="0.0020125" iyz="0" izz="0.0013417" /> -->
    </inertial>
    <visual>
      <origin rpy="0 0 0" xyz="0 0 0"/>
      <geometry>
        <mesh filename="package://reem_description/meshes/arm/arm_2.dae" scale="1 1 1.0"/>
      </geometry>
      <material name="DarkGrey"/>
    </visual>
    <collision>
      <origin rpy="0 0 0" xyz="0 0 0"/>
      <geometry>
        <mesh filename="package://reem_description/meshes/arm/arm_2_collision.stl" scale="1 1 1.0"/>
      </geometry>
    </collision>
  </link>
  <joint name="arm_left_2_joint" type="revolute">
    <parent link="arm_left_1_link"/>
    <child link="arm_left_2_link"/>
    <origin rpy="1.57079632679 1.308996939 1.57079632679" xyz="0 0 -0.2385"/>
    <axis xyz="0 0 1"/>
    <limit effort="21.7" lower="-0.261799387799" upper="2.09439510239" velocity="1.0"/>
    <dynamics damping="1.5" friction="1.0"/>
  </joint>
  <link name="arm_left_3_link">
    <inertial>
      <origin rpy="0 0 0" xyz="0.00045 -0.01547 -0.07654"/>
      <mass value="1.656"/>
      <inertia ixx="0" ixy="0" ixz="0" iyy="0" iyz="0" izz="0"/>
      <!-- NOTE: Assuming cylinder centered at CoM with r=0.05, h=0.05 with axis parallel to x coordinate -->
      <!--         <inertia ixx="0.0020700"  ixy="0"  ixz="0" iyy="0.0013800" iyz="0" izz="0.0013800" /> -->
    </inertial>
    <visual>
      <origin rpy="0 0 0" xyz="0 0 0"/>
      <geometry>
        <mesh filename="package://reem_description/meshes/arm/arm_3.dae" scale="1 1 1.0"/>
      </geometry>
      <material name="DarkGrey"/>
    </visual>
    <collision>
      <origin rpy="0 0 0" xyz="0 0 0"/>
      <geometry>
        <mesh filename="package://reem_description/meshes/arm/arm_3_collision.stl" scale="1 1 1.0"/>
      </geometry>
    </collision>
  </link>
  <joint name="arm_left_3_joint" type="revolute">
    <parent link="arm_left_2_link"/>
    <child link="arm_left_3_link"/>
    <origin rpy="-1.57079632679 0 0" xyz="0.02 -0.142 0"/>
    <axis xyz="0 0 1"/>
    <limit effort="17.4" lower="-2.35619449019" upper="2.74889357189" velocity="1.0"/>
    <dynamics damping="1.5" friction="1.0"/>
  </joint>
  <link name="arm_left_4_link">
    <inertial>
      <origin rpy="0 0 0" xyz="-0.06424 0.01712 0.00666"/>
      <mass value="1.013"/>
      <inertia ixx="0" ixy="0" ixz="0" iyy="0" iyz="0" izz="0"/>
      <!-- NOTE: Assuming cylinder centered at CoM with r=0.05, h=0.05 with axis parallel to x coordinate -->
      <!--         <inertia ixx="0.0012663"  ixy="0"  ixz="0" iyy="0.00084417" iyz="0" izz="0.00084417" /> -->
    </inertial>
    <visual>
      <origin rpy="0 0 0" xyz="0 0 0"/>
      <geometry>
        <mesh filename="package://reem_description/meshes/arm/arm_4.dae" scale="1 1 1.0"/>
      </geometry>
      <material name="DarkGrey"/>
    </visual>
    <collision>
      <origin rpy="0 0 0" xyz="0 0 0"/>
      <geometry>
        <mesh filename="package://reem_description/meshes/arm/arm_4_collision.stl" scale="1 1 1.0"/>
      </geometry>
    </collision>
  </link>
  <joint name="arm_left_4_joint" type="revolute">
    <parent link="arm_left_3_link"/>
    <child link="arm_left_4_link"/>
    <origin rpy="0 -1.57079632679 0" xyz="0 -0.02 -0.088"/>
    <axis xyz="0 0 1"/>
    <limit effort="17.4" lower="0" upper="2.26892802759" velocity="1.0"/>
    <dynamics damping="1.5" friction="1.0"/>
  </joint>
  <link name="arm_left_5_link">
    <inertial>
      <origin rpy="0 0 0" xyz="-0.00045 -0.00009 -0.08726"/>
      <mass value="1.858"/>
      <inertia ixx="0" ixy="0" ixz="0" iyy="0" iyz="0" izz="0"/>
      <!-- NOTE: Assuming cylinder centered at CoM with r=0.05, h=0.1 with axis parallel to z coordinate -->
      <!--         <inertia ixx="0.0027096"  ixy="0"  ixz="0" iyy="0.0027096" iyz="0" izz="0.0023225" /> -->
    </inertial>
    <visual>
      <origin rpy="0 0 0" xyz="0 0 0"/>
      <geometry>
        <mesh filename="package://reem_description/meshes/arm/arm_5.dae" scale="1 1 1.0"/>
      </geometry>
      <material name="LightGrey"/>
    </visual>
    <collision>
      <origin rpy="0 0 0" xyz="0 0 0"/>
      <geometry>
        <mesh filename="package://reem_description/meshes/arm/arm_5_collision.stl" scale="1 1 1.0"/>
      </geometry>
    </collision>
  </link>
  <joint name="arm_left_5_joint" type="revolute">
    <parent link="arm_left_4_link"/>
    <child link="arm_left_5_link"/>
    <origin rpy="0 1.57079632679 0" xyz="-0.088 0.02 0"/>
    <axis xyz="0 0 1"/>
    <limit effort="16" lower="-2.09439510239" upper="2.09439510239" velocity="1.0"/>
    <!--TODO: Check effort value!-->
    <dynamics damping="0.5" friction="1.0"/>
  </joint>
  <link name="arm_left_6_link">
    <inertial>
      <origin rpy="0 0 0" xyz="-0.0002 -0.01155 -2e-05"/>
      <mass value="0.255"/>
      <inertia ixx="0" ixy="0" ixz="0" iyy="0" iyz="0" izz="0"/>
      <!-- NOTE: Assuming cylinder centered at CoM with r=0.02, h=0.08 with axis parallel to z coordinate -->
      <!--         <inertia ixx="0.0001615"  ixy="0"  ixz="0" iyy="0.0001615" iyz="0" izz="0.000051" /> -->
    </inertial>
    <visual>
      <origin rpy="0 0 0" xyz="0 0 0"/>
      <geometry>
        <mesh filename="package://reem_description/meshes/arm/arm_6.dae" scale="1 1 1.0"/>
      </geometry>
      <material name="LightGrey"/>
    </visual>
    <collision>
      <origin rpy="0 0 0" xyz="0 0 0"/>
      <geometry>
        <cylinder length="0.0385" radius="0.04"/>
      </geometry>
    </collision>
  </link>
  <joint name="arm_left_6_joint" type="revolute">
    <parent link="arm_left_5_link"/>
    <child link="arm_left_6_link"/>
    <origin rpy="1.57079632679 0 0" xyz="0 0 -0.15"/>
    <axis xyz="0 0 1"/>
    <limit effort="12" lower="-1.57079632679" upper="1.57079632679" velocity="1.0"/>
    <dynamics damping="0.1" friction="1.0"/>
  </joint>
  <link name="arm_left_7_link">
    <inertial>
      <!--TODO: Verify these inertial parameters-->
      <origin rpy="0 0 0" xyz="0 0 -0.0547022545"/>
      <mass value="0.152461831"/>
      <inertia ixx="0" ixy="0" ixz="0" iyy="0" iyz="0" izz="0"/>
      <!-- NOTE: Assuming point mass -->
      <!--         <inertia ixx="0"  ixy="0"  ixz="0" iyy="0" iyz="0" izz="0" /> -->
    </inertial>
    <visual>
      <origin rpy="0 0 0" xyz="0 0 -0.046"/>
      <geometry>
        <cylinder length="0.005" radius="0.02"/>
      </geometry>
      <material name="DarkGrey"/>
    </visual>
    <collision>
      <origin rpy="0 0 0" xyz="0 0 -0.0345"/>
      <geometry>
        <cylinder length="0.023" radius="0.02"/>
      </geometry>
    </collision>
  </link>
  <joint name="arm_left_7_joint" type="revolute">
    <parent link="arm_left_6_link"/>
    <child link="arm_left_7_link"/>
    <origin rpy="-1.57079632679 0 0" xyz="0 0 0"/>
    <axis xyz="0 0 1"/>
    <limit effort="12" lower="-2.09439510239" upper="2.09439510239" velocity="1.0"/>
    <dynamics damping="0.1" friction="1.0"/>
  </joint>
  <transmission name="arm_left_5_trans" type="pr2_mechanism_model/SimpleTransmission">
    <actuator name="arm_left_5_motor"/>
    <joint name="arm_left_5_joint"/>
    <mechanicalReduction>336.0</mechanicalReduction>
  </transmission>
  <transmission name="arm_left_6_trans" type="pr2_mechanism_model/SimpleTransmission">
    <actuator name="arm_left_6_motor"/>
    <joint name="arm_left_6_joint"/>
    <mechanicalReduction>336.0</mechanicalReduction>
  </transmission>
  <transmission name="arm_left_7_trans" type="pr2_mechanism_model/SimpleTransmission">
    <actuator name="arm_left_7_motor"/>
    <joint name="arm_left_7_joint"/>
    <mechanicalReduction>336.0</mechanicalReduction>
  </transmission>
  <link name="arm_left_tool_link">
    <inertial>
      <mass value="0.1"/>
      <inertia ixx="0.0" ixy="0.0" ixz="0.0" iyy="0.0" iyz="0.0" izz="0.0"/>
    </inertial>
    <visual>
      <origin rpy="0 1.57079632679 0" xyz="0.001 0 0"/>
      <geometry>
        <cylinder length="0.005" radius="0.005"/>
      </geometry>
      <material name="LightGrey"/>
    </visual>
    <collision>
      <origin rpy="0 1.57079632679 0" xyz="0.001 0 0"/>
      <geometry>
        <cylinder length="0.005" radius="0.005"/>
      </geometry>
    </collision>
  </link>
  <joint name="arm_left_tool_joint" type="fixed">
    <parent link="arm_left_7_link"/>
    <child link="arm_left_tool_link"/>
    <origin rpy="1.57079632679 1.57079632679 0" xyz="0 0 -0.046"/>
  </joint>
  <transmission name="arm_left_1_trans" type="pr2_mechanism_model/SimpleTransmission">
    <actuator name="arm_left_1_motor"/>
    <joint name="arm_left_1_joint"/>
    <mechanicalReduction>100.0</mechanicalReduction>
  </transmission>
  <transmission name="arm_left_2_trans" type="pr2_mechanism_model/SimpleTransmission">
    <actuator name="arm_left_2_motor"/>
    <joint name="arm_left_2_joint"/>
    <mechanicalReduction>100.0</mechanicalReduction>
  </transmission>
  <transmission name="arm_left_3_trans" type="pr2_mechanism_model/SimpleTransmission">
    <actuator name="arm_left_3_motor"/>
    <joint name="arm_left_3_joint"/>
    <mechanicalReduction>80.0</mechanicalReduction>
  </transmission>
  <transmission name="arm_left_4_trans" type="pr2_mechanism_model/SimpleTransmission">
    <actuator name="arm_left_4_motor"/>
    <joint name="arm_left_4_joint"/>
    <mechanicalReduction>80.0</mechanicalReduction>
  </transmission>
  <joint name="hand_right_palm_joint" type="fixed">
    <parent link="arm_right_tool_link"/>
    <child link="hand_right_palm_link"/>
    <origin rpy="0 0 0" xyz="0 0 0"/>
  </joint>
  <link name="hand_right_palm_link">
    <inertial>
      <!--<origin xyz="0.07547 ${-reflect * 0.00468} 0.00291" rpy="0 0 0" />-->
      <origin rpy="0 0 0" xyz="0 -0.07547 0 "/>
      <!--TODO: This does not make sense!, there must be a bug in how Gazebo bungles the CoM of a chain of fixed joints-->
      <mass value="0.41066"/>
      <!--NOTE: Assigning 0.05kg to each of the ten phalanxes-->
      <inertia ixx="0" ixy="0" ixz="0" iyy="0" iyz="0" izz="0"/>
    </inertial>
    <visual>
      <origin rpy="0 0 0" xyz="0 0 0"/>
      <geometry>
        <mesh filename="package://reem_description/meshes/hand/hand_palm.dae" scale="1 -1.0 1"/>
      </geometry>
      <material name="LightGrey"/>
    </visual>
    <collision>
      <origin rpy="0 0 0" xyz="0 0 0"/>
      <geometry>
        <mesh filename="package://reem_description/meshes/hand/hand_palm_collision.stl" scale="1 -1.0 1"/>
      </geometry>
    </collision>
  </link>
  <xacro:hand_gazebo name="hand_right_palm"/>
  <joint name="hand_right_thumb_joint" type="revolute">
    <parent link="hand_right_palm_link"/>
    <child link="hand_right_thumb_link"/>
    <origin rpy="3.14159265359 1.79768912955 0.226892802759" xyz="0.03649 0.008  0.02"/>
    <axis xyz="0 0 1"/>
    <!--       <limit lower="${0.0 * deg_to_rad}" upper="${92.0 * deg_to_rad}" effort="2.0" velocity="${hand_max_vel}" /> -->
    <limit effort="2.0" lower="0.0" upper="1.57079632679" velocity="1.0"/>
    <!--TODO: Restore!-->
    <dynamics damping="0.5" friction="0.0"/>
  </joint>
  <link name="hand_right_thumb_link">
    <inertial>
      <origin rpy="0 0 0" xyz="0 0 0"/>
      <!--TODO: Fill up-->
      <mass value="0.05"/>
      <inertia ixx="0" ixy="0" ixz="0" iyy="0" iyz="0" izz="0"/>
      <!--TODO: Fill up-->
    </inertial>
    <visual>
      <origin rpy="0 0 0" xyz="-0.015 0 0"/>
      <!--NOTE: Apply offset-->
      <geometry>
        <mesh filename="package://reem_description/meshes/hand/hand_thumb.dae" scale="1 1 -1.0"/>
      </geometry>
      <material name="LightGrey"/>
    </visual>
    <collision>
      <origin rpy="0 0 0" xyz="-0.015 0 0"/>
      <!--NOTE: Apply offset-->
      <geometry>
        <mesh filename="package://reem_description/meshes/hand/hand_thumb_collision.stl" scale="1 1 -1.0"/>
      </geometry>
    </collision>
  </link>
  <transmission name="hand_right_thumb_trans" type="pr2_mechanism_model/SimpleTransmission">
    <actuator name="hand_right_thumb_motor"/>
    <joint name="hand_right_thumb_joint"/>
    <mechanicalReduction>168</mechanicalReduction>
  </transmission>
  <joint name="hand_right_index_1_joint" type="revolute">
    <parent link="hand_right_palm_link"/>
    <child link="hand_right_index_1_link"/>
    <origin rpy="0.0 0 1.57079632679" xyz="0.101 0.0025 0.0165"/>
    <axis xyz="0 0 1"/>
    <limit effort="2.0" lower="0.0" upper="1.57079632679" velocity="1.0"/>
    <dynamics damping="0.5" friction="0.0"/>
  </joint>
  <link name="hand_right_index_1_link">
    <inertial>
      <origin rpy="0 0 0" xyz="0 0 0"/>
      <!--TODO: Fill up-->
      <mass value="0.05"/>
      <inertia ixx="0" ixy="0" ixz="0" iyy="0" iyz="0" izz="0"/>
      <!--TODO: Fill up-->
    </inertial>
    <visual>
      <origin rpy="0 0 0" xyz="0 0 0"/>
      <geometry>
        <mesh filename="package://reem_description/meshes/hand/hand_finger_1.dae" scale="1 1 -1.0"/>
      </geometry>
      <material name="LightGrey"/>
    </visual>
    <collision>
      <origin rpy="0 0 0" xyz="0 0 0"/>
      <geometry>
        <mesh filename="package://reem_description/meshes/hand/hand_finger_1_collision.stl" scale="1 1 -1.0"/>
      </geometry>
    </collision>
  </link>
  <joint name="hand_right_index_2_joint" type="revolute">
    <parent link="hand_right_index_1_link"/>
    <child link="hand_right_index_2_link"/>
    <origin rpy="0 0 0" xyz="0.00357 -0.04084 0"/>
    <axis xyz="0 0 1"/>
    <!--       <limit lower="${0.0 * deg_to_rad}" upper="${80.0 * deg_to_rad}" effort="1.0" velocity="${hand_max_vel}" /> -->
    <!--TODO: Restore!-->
    <limit effort="1.0" lower="0.0" upper="0.0174532925199" velocity="1.0"/>
    <dynamics damping="0.5" friction="0.0"/>
    <mimic joint="hand_right_index_1_joint" multiplier="1" offset="0"/>
  </joint>
  <link name="hand_right_index_2_link">
    <inertial>
      <origin rpy="0 0 0" xyz="0 0 0"/>
      <!--TODO: Fill up-->
      <mass value="0.05"/>
      <inertia ixx="0" ixy="0" ixz="0" iyy="0" iyz="0" izz="0"/>
      <!--TODO: Fill up-->
    </inertial>
    <visual>
      <origin rpy="0 0 0" xyz="0 0 0"/>
      <geometry>
        <mesh filename="package://reem_description/meshes/hand/hand_finger_2.dae" scale="1 1 -1.0"/>
      </geometry>
      <material name="LightGrey"/>
    </visual>
    <collision>
      <origin rpy="0 0 0" xyz="0 0 0"/>
      <geometry>
        <mesh filename="package://reem_description/meshes/hand/hand_finger_2_collision.stl" scale="1 1 -1.0"/>
      </geometry>
    </collision>
  </link>
  <joint name="hand_right_index_3_joint" type="revolute">
    <parent link="hand_right_index_2_link"/>
    <child link="hand_right_index_3_link"/>
    <origin rpy="0 0 0" xyz="0.00572 -0.0269 0"/>
    <axis xyz="0 0 1"/>
    <!--<limit lower="${0.0 * deg_to_rad}" upper="${80.0 * deg_to_rad}" effort="1.0" velocity="${hand_max_vel}" />-->
    <!--TODO: Restore!-->
    <limit effort="1.0" lower="0.0" upper="0.0174532925199" velocity="1.0"/>
    <dynamics damping="0.5" friction="0.0"/>
    <mimic joint="hand_right_index_2_joint" multiplier="1" offset="0"/>
  </joint>
  <link name="hand_right_index_3_link">
    <inertial>
      <origin rpy="0 0 0" xyz="0 0 0"/>
      <!--TODO: Fill up-->
      <mass value="0.05"/>
      <inertia ixx="0" ixy="0" ixz="0" iyy="0" iyz="0" izz="0"/>
      <!--TODO: Fill up-->
    </inertial>
    <visual>
      <origin rpy="0 0 0" xyz="0 0 0"/>
      <geometry>
        <mesh filename="package://reem_description/meshes/hand/hand_finger_3.dae" scale="1 1 -1.0"/>
      </geometry>
      <material name="LightGrey"/>
    </visual>
    <collision>
      <origin rpy="0 0 0" xyz="0 0 0"/>
      <geometry>
        <mesh filename="package://reem_description/meshes/hand/hand_finger_3_collision.stl" scale="1 1 -1.0"/>
      </geometry>
    </collision>
  </link>
  <transmission name="hand_right_index_1_trans" type="pr2_mechanism_model/SimpleTransmission">
    <actuator name="hand_right_index_1_motor"/>
    <joint name="hand_right_index_1_joint"/>
    <mechanicalReduction>200</mechanicalReduction>
  </transmission>
  <transmission name="hand_right_index_2_trans" type="pr2_mechanism_model/SimpleTransmission">
    <actuator name="hand_right_index_2_motor"/>
    <joint name="hand_right_index_2_joint"/>
    <mechanicalReduction>200</mechanicalReduction>
  </transmission>
  <transmission name="hand_right_index_3_trans" type="pr2_mechanism_model/SimpleTransmission">
    <actuator name="hand_right_index_3_motor"/>
    <joint name="hand_right_index_3_joint"/>
    <mechanicalReduction>200</mechanicalReduction>
  </transmission>
  <joint name="hand_right_middle_1_joint" type="revolute">
    <parent link="hand_right_palm_link"/>
    <child link="hand_right_middle_1_link"/>
    <origin rpy="0.0 0 1.57079632679" xyz="0.101 0.0025 -0.0165"/>
    <axis xyz="0 0 1"/>
    <limit effort="2.0" lower="0.0" upper="1.57079632679" velocity="1.0"/>
    <dynamics damping="0.5" friction="0.0"/>
  </joint>
  <link name="hand_right_middle_1_link">
    <inertial>
      <origin rpy="0 0 0" xyz="0 0 0"/>
      <!--TODO: Fill up-->
      <mass value="0.05"/>
      <inertia ixx="0" ixy="0" ixz="0" iyy="0" iyz="0" izz="0"/>
      <!--TODO: Fill up-->
    </inertial>
    <visual>
      <origin rpy="0 0 0" xyz="0 0 0"/>
      <geometry>
        <mesh filename="package://reem_description/meshes/hand/hand_finger_1.dae" scale="1 1 1.0"/>
      </geometry>
      <material name="LightGrey"/>
    </visual>
    <collision>
      <origin rpy="0 0 0" xyz="0 0 0"/>
      <geometry>
        <mesh filename="package://reem_description/meshes/hand/hand_finger_1_collision.stl" scale="1 1 1.0"/>
      </geometry>
    </collision>
  </link>
  <joint name="hand_right_middle_2_joint" type="revolute">
    <parent link="hand_right_middle_1_link"/>
    <child link="hand_right_middle_2_link"/>
    <origin rpy="0 0 0" xyz="0.00357 -0.04084 0"/>
    <axis xyz="0 0 1"/>
    <!--       <limit lower="${0.0 * deg_to_rad}" upper="${80.0 * deg_to_rad}" effort="1.0" velocity="${hand_max_vel}" /> -->
    <!--TODO: Restore!-->
    <limit effort="1.0" lower="0.0" upper="0.0174532925199" velocity="1.0"/>
    <dynamics damping="0.5" friction="0.0"/>
    <mimic joint="hand_right_middle_1_joint" multiplier="1" offset="0"/>
  </joint>
  <link name="hand_right_middle_2_link">
    <inertial>
      <origin rpy="0 0 0" xyz="0 0 0"/>
      <!--TODO: Fill up-->
      <mass value="0.05"/>
      <inertia ixx="0" ixy="0" ixz="0" iyy="0" iyz="0" izz="0"/>
      <!--TODO: Fill up-->
    </inertial>
    <visual>
      <origin rpy="0 0 0" xyz="0 0 0"/>
      <geometry>
        <mesh filename="package://reem_description/meshes/hand/hand_finger_2.dae" scale="1 1 1.0"/>
      </geometry>
      <material name="LightGrey"/>
    </visual>
    <collision>
      <origin rpy="0 0 0" xyz="0 0 0"/>
      <geometry>
        <mesh filename="package://reem_description/meshes/hand/hand_finger_2_collision.stl" scale="1 1 1.0"/>
      </geometry>
    </collision>
  </link>
  <joint name="hand_right_middle_3_joint" type="revolute">
    <parent link="hand_right_middle_2_link"/>
    <child link="hand_right_middle_3_link"/>
    <origin rpy="0 0 0" xyz="0.00572 -0.0269 0"/>
    <axis xyz="0 0 1"/>
    <!--<limit lower="${0.0 * deg_to_rad}" upper="${80.0 * deg_to_rad}" effort="1.0" velocity="${hand_max_vel}" />-->
    <!--TODO: Restore!-->
    <limit effort="1.0" lower="0.0" upper="0.0174532925199" velocity="1.0"/>
    <dynamics damping="0.5" friction="0.0"/>
    <mimic joint="hand_right_middle_2_joint" multiplier="1" offset="0"/>
  </joint>
  <link name="hand_right_middle_3_link">
    <inertial>
      <origin rpy="0 0 0" xyz="0 0 0"/>
      <!--TODO: Fill up-->
      <mass value="0.05"/>
      <inertia ixx="0" ixy="0" ixz="0" iyy="0" iyz="0" izz="0"/>
      <!--TODO: Fill up-->
    </inertial>
    <visual>
      <origin rpy="0 0 0" xyz="0 0 0"/>
      <geometry>
        <mesh filename="package://reem_description/meshes/hand/hand_finger_3.dae" scale="1 1 1.0"/>
      </geometry>
      <material name="LightGrey"/>
    </visual>
    <collision>
      <origin rpy="0 0 0" xyz="0 0 0"/>
      <geometry>
        <mesh filename="package://reem_description/meshes/hand/hand_finger_3_collision.stl" scale="1 1 1.0"/>
      </geometry>
    </collision>
  </link>
  <transmission name="hand_right_middle_1_trans" type="pr2_mechanism_model/SimpleTransmission">
    <actuator name="hand_right_middle_1_motor"/>
    <joint name="hand_right_middle_1_joint"/>
    <mechanicalReduction>200</mechanicalReduction>
  </transmission>
  <transmission name="hand_right_middle_2_trans" type="pr2_mechanism_model/SimpleTransmission">
    <actuator name="hand_right_middle_2_motor"/>
    <joint name="hand_right_middle_2_joint"/>
    <mechanicalReduction>200</mechanicalReduction>
  </transmission>
  <transmission name="hand_right_middle_3_trans" type="pr2_mechanism_model/SimpleTransmission">
    <actuator name="hand_right_middle_3_motor"/>
    <joint name="hand_right_middle_3_joint"/>
    <mechanicalReduction>200</mechanicalReduction>
  </transmission>
  <gazebo>
    <gripper name="right_grasp_hack">
      <!--<grasp_check attach_steps="20" detach_steps="40" min_contact_count="2" />-->
      <grasp_check>
        <attach_steps>20</attach_steps>
        <detach_steps>20</detach_steps>
        <min_contact_count>20</min_contact_count>
      </grasp_check>
      <gripper_link>hand_right_middle_1_link</gripper_link>
      <gripper_link>hand_right_index_1_link</gripper_link>
      <gripper_link>hand_right_middle_2_link</gripper_link>
      <gripper_link>hand_right_index_2_link</gripper_link>
      <gripper_link>hand_right_middle_3_link</gripper_link>
      <gripper_link>hand_right_index_3_link</gripper_link>
      <palm_link>hand_right_thumb_link</palm_link>
    </gripper>
  </gazebo>
  <joint name="hand_left_palm_joint" type="fixed">
    <parent link="arm_left_tool_link"/>
    <child link="hand_left_palm_link"/>
    <origin rpy="0 0 0" xyz="0 0 0"/>
  </joint>
  <link name="hand_left_palm_link">
    <inertial>
      <!--<origin xyz="0.07547 ${-reflect * 0.00468} 0.00291" rpy="0 0 0" />-->
      <origin rpy="0 0 0" xyz="0 0.07547 0 "/>
      <!--TODO: This does not make sense!, there must be a bug in how Gazebo bungles the CoM of a chain of fixed joints-->
      <mass value="0.41066"/>
      <!--NOTE: Assigning 0.05kg to each of the ten phalanxes-->
      <inertia ixx="0" ixy="0" ixz="0" iyy="0" iyz="0" izz="0"/>
    </inertial>
    <visual>
      <origin rpy="0 0 0" xyz="0 0 0"/>
      <geometry>
        <mesh filename="package://reem_description/meshes/hand/hand_palm.dae" scale="1 1.0 1"/>
      </geometry>
      <material name="LightGrey"/>
    </visual>
    <collision>
      <origin rpy="0 0 0" xyz="0 0 0"/>
      <geometry>
        <mesh filename="package://reem_description/meshes/hand/hand_palm_collision.stl" scale="1 1.0 1"/>
      </geometry>
    </collision>
  </link>
  <xacro:hand_gazebo name="hand_left_palm"/>
  <joint name="hand_left_thumb_joint" type="revolute">
    <parent link="hand_left_palm_link"/>
    <child link="hand_left_thumb_link"/>
    <origin rpy="0.0 1.79768912955 -0.226892802759" xyz="0.03649 -0.008  0.02"/>
    <axis xyz="0 0 1"/>
    <!--       <limit lower="${0.0 * deg_to_rad}" upper="${92.0 * deg_to_rad}" effort="2.0" velocity="${hand_max_vel}" /> -->
    <limit effort="2.0" lower="0.0" upper="1.57079632679" velocity="1.0"/>
    <!--TODO: Restore!-->
    <dynamics damping="0.5" friction="0.0"/>
  </joint>
  <link name="hand_left_thumb_link">
    <inertial>
      <origin rpy="0 0 0" xyz="0 0 0"/>
      <!--TODO: Fill up-->
      <mass value="0.05"/>
      <inertia ixx="0" ixy="0" ixz="0" iyy="0" iyz="0" izz="0"/>
      <!--TODO: Fill up-->
    </inertial>
    <visual>
      <origin rpy="0 0 0" xyz="-0.015 0 0"/>
      <!--NOTE: Apply offset-->
      <geometry>
        <mesh filename="package://reem_description/meshes/hand/hand_thumb.dae" scale="1 1 1.0"/>
      </geometry>
      <material name="LightGrey"/>
    </visual>
    <collision>
      <origin rpy="0 0 0" xyz="-0.015 0 0"/>
      <!--NOTE: Apply offset-->
      <geometry>
        <mesh filename="package://reem_description/meshes/hand/hand_thumb_collision.stl" scale="1 1 1.0"/>
      </geometry>
    </collision>
  </link>
  <transmission name="hand_left_thumb_trans" type="pr2_mechanism_model/SimpleTransmission">
    <actuator name="hand_left_thumb_motor"/>
    <joint name="hand_left_thumb_joint"/>
    <mechanicalReduction>168</mechanicalReduction>
  </transmission>
  <joint name="hand_left_index_1_joint" type="revolute">
    <parent link="hand_left_palm_link"/>
    <child link="hand_left_index_1_link"/>
    <origin rpy="3.14159265359 0 -1.57079632679" xyz="0.101 -0.0025 0.0165"/>
    <axis xyz="0 0 1"/>
    <limit effort="2.0" lower="0.0" upper="1.57079632679" velocity="1.0"/>
    <dynamics damping="0.5" friction="0.0"/>
  </joint>
  <link name="hand_left_index_1_link">
    <inertial>
      <origin rpy="0 0 0" xyz="0 0 0"/>
      <!--TODO: Fill up-->
      <mass value="0.05"/>
      <inertia ixx="0" ixy="0" ixz="0" iyy="0" iyz="0" izz="0"/>
      <!--TODO: Fill up-->
    </inertial>
    <visual>
      <origin rpy="0 0 0" xyz="0 0 0"/>
      <geometry>
        <mesh filename="package://reem_description/meshes/hand/hand_finger_1.dae" scale="1 1 1.0"/>
      </geometry>
      <material name="LightGrey"/>
    </visual>
    <collision>
      <origin rpy="0 0 0" xyz="0 0 0"/>
      <geometry>
        <mesh filename="package://reem_description/meshes/hand/hand_finger_1_collision.stl" scale="1 1 1.0"/>
      </geometry>
    </collision>
  </link>
  <joint name="hand_left_index_2_joint" type="revolute">
    <parent link="hand_left_index_1_link"/>
    <child link="hand_left_index_2_link"/>
    <origin rpy="0 0 0" xyz="0.00357 -0.04084 0"/>
    <axis xyz="0 0 1"/>
    <!--       <limit lower="${0.0 * deg_to_rad}" upper="${80.0 * deg_to_rad}" effort="1.0" velocity="${hand_max_vel}" /> -->
    <!--TODO: Restore!-->
    <limit effort="1.0" lower="0.0" upper="0.0174532925199" velocity="1.0"/>
    <dynamics damping="0.5" friction="0.0"/>
    <mimic joint="hand_left_index_1_joint" multiplier="1" offset="0"/>
  </joint>
  <link name="hand_left_index_2_link">
    <inertial>
      <origin rpy="0 0 0" xyz="0 0 0"/>
      <!--TODO: Fill up-->
      <mass value="0.05"/>
      <inertia ixx="0" ixy="0" ixz="0" iyy="0" iyz="0" izz="0"/>
      <!--TODO: Fill up-->
    </inertial>
    <visual>
      <origin rpy="0 0 0" xyz="0 0 0"/>
      <geometry>
        <mesh filename="package://reem_description/meshes/hand/hand_finger_2.dae" scale="1 1 1.0"/>
      </geometry>
      <material name="LightGrey"/>
    </visual>
    <collision>
      <origin rpy="0 0 0" xyz="0 0 0"/>
      <geometry>
        <mesh filename="package://reem_description/meshes/hand/hand_finger_2_collision.stl" scale="1 1 1.0"/>
      </geometry>
    </collision>
  </link>
  <joint name="hand_left_index_3_joint" type="revolute">
    <parent link="hand_left_index_2_link"/>
    <child link="hand_left_index_3_link"/>
    <origin rpy="0 0 0" xyz="0.00572 -0.0269 0"/>
    <axis xyz="0 0 1"/>
    <!--<limit lower="${0.0 * deg_to_rad}" upper="${80.0 * deg_to_rad}" effort="1.0" velocity="${hand_max_vel}" />-->
    <!--TODO: Restore!-->
    <limit effort="1.0" lower="0.0" upper="0.0174532925199" velocity="1.0"/>
    <dynamics damping="0.5" friction="0.0"/>
    <mimic joint="hand_left_index_2_joint" multiplier="1" offset="0"/>
  </joint>
  <link name="hand_left_index_3_link">
    <inertial>
      <origin rpy="0 0 0" xyz="0 0 0"/>
      <!--TODO: Fill up-->
      <mass value="0.05"/>
      <inertia ixx="0" ixy="0" ixz="0" iyy="0" iyz="0" izz="0"/>
      <!--TODO: Fill up-->
    </inertial>
    <visual>
      <origin rpy="0 0 0" xyz="0 0 0"/>
      <geometry>
        <mesh filename="package://reem_description/meshes/hand/hand_finger_3.dae" scale="1 1 1.0"/>
      </geometry>
      <material name="LightGrey"/>
    </visual>
    <collision>
      <origin rpy="0 0 0" xyz="0 0 0"/>
      <geometry>
        <mesh filename="package://reem_description/meshes/hand/hand_finger_3_collision.stl" scale="1 1 1.0"/>
      </geometry>
    </collision>
  </link>
  <transmission name="hand_left_index_1_trans" type="pr2_mechanism_model/SimpleTransmission">
    <actuator name="hand_left_index_1_motor"/>
    <joint name="hand_left_index_1_joint"/>
    <mechanicalReduction>200</mechanicalReduction>
  </transmission>
  <transmission name="hand_left_index_2_trans" type="pr2_mechanism_model/SimpleTransmission">
    <actuator name="hand_left_index_2_motor"/>
    <joint name="hand_left_index_2_joint"/>
    <mechanicalReduction>200</mechanicalReduction>
  </transmission>
  <transmission name="hand_left_index_3_trans" type="pr2_mechanism_model/SimpleTransmission">
    <actuator name="hand_left_index_3_motor"/>
    <joint name="hand_left_index_3_joint"/>
    <mechanicalReduction>200</mechanicalReduction>
  </transmission>
  <joint name="hand_left_middle_1_joint" type="revolute">
    <parent link="hand_left_palm_link"/>
    <child link="hand_left_middle_1_link"/>
    <origin rpy="3.14159265359 0 -1.57079632679" xyz="0.101 -0.0025 -0.0165"/>
    <axis xyz="0 0 1"/>
    <limit effort="2.0" lower="0.0" upper="1.57079632679" velocity="1.0"/>
    <dynamics damping="0.5" friction="0.0"/>
  </joint>
  <link name="hand_left_middle_1_link">
    <inertial>
      <origin rpy="0 0 0" xyz="0 0 0"/>
      <!--TODO: Fill up-->
      <mass value="0.05"/>
      <inertia ixx="0" ixy="0" ixz="0" iyy="0" iyz="0" izz="0"/>
      <!--TODO: Fill up-->
    </inertial>
    <visual>
      <origin rpy="0 0 0" xyz="0 0 0"/>
      <geometry>
        <mesh filename="package://reem_description/meshes/hand/hand_finger_1.dae" scale="1 1 -1.0"/>
      </geometry>
      <material name="LightGrey"/>
    </visual>
    <collision>
      <origin rpy="0 0 0" xyz="0 0 0"/>
      <geometry>
        <mesh filename="package://reem_description/meshes/hand/hand_finger_1_collision.stl" scale="1 1 -1.0"/>
      </geometry>
    </collision>
  </link>
  <joint name="hand_left_middle_2_joint" type="revolute">
    <parent link="hand_left_middle_1_link"/>
    <child link="hand_left_middle_2_link"/>
    <origin rpy="0 0 0" xyz="0.00357 -0.04084 0"/>
    <axis xyz="0 0 1"/>
    <!--       <limit lower="${0.0 * deg_to_rad}" upper="${80.0 * deg_to_rad}" effort="1.0" velocity="${hand_max_vel}" /> -->
    <!--TODO: Restore!-->
    <limit effort="1.0" lower="0.0" upper="0.0174532925199" velocity="1.0"/>
    <dynamics damping="0.5" friction="0.0"/>
    <mimic joint="hand_left_middle_1_joint" multiplier="1" offset="0"/>
  </joint>
  <link name="hand_left_middle_2_link">
    <inertial>
      <origin rpy="0 0 0" xyz="0 0 0"/>
      <!--TODO: Fill up-->
      <mass value="0.05"/>
      <inertia ixx="0" ixy="0" ixz="0" iyy="0" iyz="0" izz="0"/>
      <!--TODO: Fill up-->
    </inertial>
    <visual>
      <origin rpy="0 0 0" xyz="0 0 0"/>
      <geometry>
        <mesh filename="package://reem_description/meshes/hand/hand_finger_2.dae" scale="1 1 -1.0"/>
      </geometry>
      <material name="LightGrey"/>
    </visual>
    <collision>
      <origin rpy="0 0 0" xyz="0 0 0"/>
      <geometry>
        <mesh filename="package://reem_description/meshes/hand/hand_finger_2_collision.stl" scale="1 1 -1.0"/>
      </geometry>
    </collision>
  </link>
  <joint name="hand_left_middle_3_joint" type="revolute">
    <parent link="hand_left_middle_2_link"/>
    <child link="hand_left_middle_3_link"/>
    <origin rpy="0 0 0" xyz="0.00572 -0.0269 0"/>
    <axis xyz="0 0 1"/>
    <!--<limit lower="${0.0 * deg_to_rad}" upper="${80.0 * deg_to_rad}" effort="1.0" velocity="${hand_max_vel}" />-->
    <!--TODO: Restore!-->
    <limit effort="1.0" lower="0.0" upper="0.0174532925199" velocity="1.0"/>
    <dynamics damping="0.5" friction="0.0"/>
    <mimic joint="hand_left_middle_2_joint" multiplier="1" offset="0"/>
  </joint>
  <link name="hand_left_middle_3_link">
    <inertial>
      <origin rpy="0 0 0" xyz="0 0 0"/>
      <!--TODO: Fill up-->
      <mass value="0.05"/>
      <inertia ixx="0" ixy="0" ixz="0" iyy="0" iyz="0" izz="0"/>
      <!--TODO: Fill up-->
    </inertial>
    <visual>
      <origin rpy="0 0 0" xyz="0 0 0"/>
      <geometry>
        <mesh filename="package://reem_description/meshes/hand/hand_finger_3.dae" scale="1 1 -1.0"/>
      </geometry>
      <material name="LightGrey"/>
    </visual>
    <collision>
      <origin rpy="0 0 0" xyz="0 0 0"/>
      <geometry>
        <mesh filename="package://reem_description/meshes/hand/hand_finger_3_collision.stl" scale="1 1 -1.0"/>
      </geometry>
    </collision>
  </link>
  <transmission name="hand_left_middle_1_trans" type="pr2_mechanism_model/SimpleTransmission">
    <actuator name="hand_left_middle_1_motor"/>
    <joint name="hand_left_middle_1_joint"/>
    <mechanicalReduction>200</mechanicalReduction>
  </transmission>
  <transmission name="hand_left_middle_2_trans" type="pr2_mechanism_model/SimpleTransmission">
    <actuator name="hand_left_middle_2_motor"/>
    <joint name="hand_left_middle_2_joint"/>
    <mechanicalReduction>200</mechanicalReduction>
  </transmission>
  <transmission name="hand_left_middle_3_trans" type="pr2_mechanism_model/SimpleTransmission">
    <actuator name="hand_left_middle_3_motor"/>
    <joint name="hand_left_middle_3_joint"/>
    <mechanicalReduction>200</mechanicalReduction>
  </transmission>
  <gazebo>
    <gripper name="left_grasp_hack">
      <!--<grasp_check attach_steps="20" detach_steps="40" min_contact_count="2" />-->
      <grasp_check>
        <attach_steps>20</attach_steps>
        <detach_steps>20</detach_steps>
        <min_contact_count>20</min_contact_count>
      </grasp_check>
      <gripper_link>hand_left_middle_1_link</gripper_link>
      <gripper_link>hand_left_index_1_link</gripper_link>
      <gripper_link>hand_left_middle_2_link</gripper_link>
      <gripper_link>hand_left_index_2_link</gripper_link>
      <gripper_link>hand_left_middle_3_link</gripper_link>
      <gripper_link>hand_left_index_3_link</gripper_link>
      <palm_link>hand_left_thumb_link</palm_link>
    </gripper>
  </gazebo>
  <link name="marker_right_hand_link">
    <inertial>
      <origin rpy="0 0 0" xyz="0.01747 0.0014 0.128"/>
      <mass value="0.01"/>
      <inertia ixx="0.1" ixy="0" ixz="0" iyy="0.1" iyz="0" izz="0.1"/>
    </inertial>
    <visual>
      <geometry>
        <mesh filename="package://reem_description/meshes/marker/hand_marker.dae"/>
      </geometry>
      <material name="DarkGrey"/>
    </visual>
    <collision>
      <origin rpy="0 0 0" xyz="0 0 0"/>
      <geometry>
        <box size="0.09 0.09 0.000000001"/>
        <!-- SIZE OF THE MARKER + MARGIN -->
      </geometry>
    </collision>
  </link>
  <joint name="marker_right_hand_joint" type="fixed">
    <parent link="arm_right_7_link"/>
    <child link="marker_right_hand_link"/>
    <origin rpy="1.57079633 0 0" xyz="0 -0.06 0.08"/>
  </joint>
  <!-- stereo camera -->
  <!-- IMPORTANT: focal_length = image_width/(2tan(hfov/2)) Ex.: f=359.000019  hfov=84.832707076 -->
  <joint name="stereo_frame_joint" type="fixed">
    <origin rpy="1.5707 0 0" xyz="0.0558343 -0.106811 0.0365"/>
    <parent link="head_2_link"/>
    <child link="stereo_link"/>
  </joint>
  <link name="stereo_link">
    <inertial>
      <mass value="0.01"/>
      <origin rpy="0 0 0" xyz="0 0 0"/>
      <inertia ixx="0" ixy="0" ixz="0" iyy="0" iyz="0" izz="0"/>
      <!-- this inertia is made up for now. -->
    </inertial>
    <visual>
      <origin rpy="0 0 0" xyz="0 0 0"/>
      <geometry>
        <box size="0.001 0.001 0.001"/>
      </geometry>
      <material name="Blue"/>
    </visual>
    <collision>
      <origin rpy="0 0 0" xyz="0 0 0"/>
      <geometry>
        <box size="0.001 0.001 0.001"/>
      </geometry>
    </collision>
  </link>
  <joint name="stereo_optical_frame_joint" type="fixed">
    <origin rpy="-1.57079632679 0.0 -1.57079632679" xyz="0 0 0"/>
    <!-- rotate frame from x-forward to z-forward camera coords -->
    <parent link="stereo_link"/>
    <child link="stereo_optical_frame"/>
  </joint>
  <link name="stereo_optical_frame" type="camera">
    <inertial>
      <mass value="0.01"/>
      <origin rpy="0 0 0" xyz="0 0 0"/>
      <inertia ixx="0" ixy="0" ixz="0" iyy="0" iyz="0" izz="0"/>
      <!-- this inertia is made up for now. -->
    </inertial>
  </link>
  <joint name="stereo_gazebo_l_stereo_camera_frame_joint" type="fixed">
    <origin rpy="0.0 0.0 0.0" xyz="0 0 0"/>
    <parent link="stereo_link"/>
    <child link="stereo_gazebo_l_stereo_camera_frame"/>
  </joint>
  <link name="stereo_gazebo_l_stereo_camera_frame">
    <inertial>
      <mass value="0.01"/>
      <origin xyz="0 0 0"/>
      <inertia ixx="0" ixy="0.0" ixz="0.0" iyy="0" iyz="0.0" izz="0"/>
    </inertial>
    <visual>
      <origin rpy="0 1.57079632679 0" xyz="-0.01 0 0"/>
      <geometry>
        <cylinder length="0.02" radius="0.01"/>
      </geometry>
      <material name="Blue"/>
    </visual>
    <!--
      <collision>
        <origin xyz="0 0 0" rpy="0 0 0"/>
        <geometry>
          <box size="0.01 0.01 0.01" />
        </geometry>
      </collision>
      -->
  </link>
  <joint name="stereo_gazebo_l_stereo_camera_optical_frame_joint" type="fixed">
    <origin rpy="-1.57079632679 0.0 -1.57079632679" xyz="0 0 0"/>
    <parent link="stereo_gazebo_l_stereo_camera_frame"/>
    <child link="stereo_gazebo_l_stereo_camera_optical_frame"/>
  </joint>
  <link name="stereo_gazebo_l_stereo_camera_optical_frame">
    <inertial>
      <mass value="0.1"/>
      <origin xyz="0 0 0"/>
      <inertia ixx="0" ixy="0.0" ixz="0.0" iyy="0" iyz="0.0" izz="0"/>
    </inertial>
  </link>
  <gazebo reference="stereo_gazebo_l_stereo_camera_frame">
    <sensor name="stereo_gazebo_l_stereo_camera_sensor" type="camera">
      <update_rate>15.0</update_rate>
      <camera name="stereo_gazebo_l_stereo_camera">
        <pose>0 0 0 0 0 0</pose>
        <horizontal_fov>1.23918376892</horizontal_fov>
        <image>
          <width>656 </width>
          <height> 492</height>
          <format>B8G8R8</format>
        </image>
        <clip>
          <near>0.01</near>
          <far>100</far>
        </clip>
      </camera>
      <plugin filename="libgazebo_ros_camera.so" name="stereo_gazebo_l_stereo_camera_controller">
        <alwaysOn>true</alwaysOn>
        <updateRate>15.0</updateRate>
        <cameraName>stereo_gazebo_l_stereo_camera</cameraName>
        <imageTopicName>/stereo/left/image</imageTopicName>
        <cameraInfoTopicName>/stereo/left/camera_info</cameraInfoTopicName>
        <frameName>stereo_optical_frame</frameName>
        <hackBaseline>0</hackBaseline>
        <CxPrime>328.5</CxPrime>
        <Cx>328.5</Cx>
        <Cy>246.5</Cy>
        <focalLength>459.838928</focalLength>
        <!-- image_width / (2*tan(hfov_radian /2)) -->
        <distortionK1>0.0</distortionK1>
        <distortionK2>0.0</distortionK2>
        <distortionK3>0.0</distortionK3>
        <distortionT1>0.0</distortionT1>
        <distortionT2>0.0</distortionT2>
      </plugin>
    </sensor>
  </gazebo>
  <joint name="stereo_gazebo_r_stereo_camera_frame_joint" type="fixed">
    <origin rpy="0.0 0.0 0.0" xyz="0.0 -0.073 0.0"/>
    <parent link="stereo_gazebo_l_stereo_camera_frame"/>
    <child link="stereo_gazebo_r_stereo_camera_frame"/>
  </joint>
  <link name="stereo_gazebo_r_stereo_camera_frame">
    <inertial>
      <mass value="0.01"/>
      <origin xyz="0 0 0"/>
      <inertia ixx="0" ixy="0.0" ixz="0.0" iyy="0" iyz="0.0" izz="0"/>
    </inertial>
    <visual>
      <origin rpy="0 1.57079632679 0" xyz="-0.01 0 0"/>
      <geometry>
        <cylinder length="0.02" radius="0.01"/>
      </geometry>
      <material name="Blue"/>
    </visual>
    <!--
      <collision>
        <origin xyz="0 0 0" rpy="0 0 0"/>
        <geometry>
          <box size="0.01 0.01 0.01" />
        </geometry>
      </collision>
      -->
  </link>
  <joint name="stereo_gazebo_r_stereo_camera_optical_frame_joint" type="fixed">
    <origin rpy="-1.57079632679 0.0 -1.57079632679" xyz="0 0 0"/>
    <parent link="stereo_gazebo_r_stereo_camera_frame"/>
    <child link="stereo_gazebo_r_stereo_camera_optical_frame"/>
  </joint>
  <link name="stereo_gazebo_r_stereo_camera_optical_frame">
    <inertial>
      <mass value="0.1"/>
      <origin xyz="0 0 0"/>
      <inertia ixx="0" ixy="0.0" ixz="0.0" iyy="0" iyz="0.0" izz="0"/>
    </inertial>
  </link>
  <gazebo reference="stereo_gazebo_r_stereo_camera_frame">
    <sensor name="stereo_gazebo_r_stereo_camera_sensor" type="camera">
      <update_rate>15.0</update_rate>
      <camera name="stereo_gazebo_r_stereo_camera">
        <pose>0.073 0 0 0 0 0</pose>
        <horizontal_fov>1.23918376892</horizontal_fov>
        <image>
          <width>656 </width>
          <height> 492</height>
          <format>B8G8R8</format>
        </image>
        <clip>
          <near>0.01</near>
          <far>100</far>
        </clip>
      </camera>
      <plugin filename="libgazebo_ros_camera.so" name="stereo_gazebo_r_stereo_camera_controller">
        <alwaysOn>true</alwaysOn>
        <updateRate>15.0</updateRate>
        <cameraName>stereo_gazebo_r_stereo_camera</cameraName>
        <imageTopicName>/stereo/right/image</imageTopicName>
        <cameraInfoTopicName>/stereo/right/camera_info</cameraInfoTopicName>
        <frameName>stereo_optical_frame</frameName>
        <hackBaseline>0.073</hackBaseline>
        <CxPrime>328.5</CxPrime>
        <Cx>328.5</Cx>
        <Cy>246.5</Cy>
        <focalLength>459.838928</focalLength>
        <!-- image_width / (2*tan(hfov_radian /2)) -->
        <distortionK1>0.0</distortionK1>
        <distortionK2>0.0</distortionK2>
        <distortionK3>0.0</distortionK3>
        <distortionT1>0.0</distortionT1>
        <distortionT2>0.0</distortionT2>
      </plugin>
    </sensor>
  </gazebo>
  <joint name="back_camera_frame_joint" type="fixed">
    <origin rpy="-1.5708  0 -2.70526" xyz="-0.127 -0.302 -0.000"/>
    <parent link="torso_2_link"/>
    <child link="back_camera_link"/>
  </joint>
  <link name="back_camera_link">
    <inertial>
      <mass value="0.05"/>
      <origin rpy="0 0 0" xyz="0 0 0"/>
      <inertia ixx="0.01" ixy="0" ixz="0" iyy="0.01" iyz="0" izz="0.01"/>
      <!-- this inertia is made up for now. -->
    </inertial>
    <visual>
      <origin rpy="0 0 0" xyz="0 0 0"/>
      <geometry>
        <box size="0.001 0.001 0.001"/>
      </geometry>
    </visual>
    <collision>
      <origin rpy="0 0 0" xyz="0 0 0"/>
      <geometry>
        <box size="0.001 0.001 0.001"/>
      </geometry>
    </collision>
  </link>
  <joint name="back_camera_optical_frame_joint" type="fixed">
    <origin rpy="-1.57079632679 0.0 -1.57079632679" xyz="0 0 0"/>
    <!-- rotate frame from x-forward to z-forward camera coords -->
    <parent link="back_camera_link"/>
    <child link="back_camera_optical_frame"/>
  </joint>
  <link name="back_camera_optical_frame" type="camera">
    <inertial>
      <mass value="0.05"/>
      <inertia ixx="0" ixy="0" ixz="0" iyy="0" iyz="0" izz="0"/>
    </inertial>
  </link>
  <joint name="back_camera_gazebo_back_camera_frame_joint" type="fixed">
    <origin rpy="0.0 0.0 0.0" xyz="0 0 0"/>
    <parent link="back_camera_link"/>
    <child link="back_camera_gazebo_back_camera_link"/>
  </joint>
  <link name="back_camera_gazebo_back_camera_link">
    <inertial>
      <mass value="0.1"/>
      <origin xyz="0 0 0"/>
      <inertia ixx="0" ixy="0.0" ixz="0.0" iyy="0" iyz="0.0" izz="0"/>
    </inertial>
    <visual>
      <origin rpy="0 1.57079632679 0" xyz="-0.01 0 0"/>
      <geometry>
        <cylinder length="0.02" radius="0.01"/>
      </geometry>
      <material name="Blue"/>
    </visual>
    <material name="Red">
      <color rgba="0.72941 0.35686 0.023529 1"/>
    </material>
  </link>
  <gazebo reference="back_camera_link">
    <sensor name="gazebo_back_camera_camera" type="camera">
      <update_rate>15.0</update_rate>
      <camera>
        <horizontal_fov>1.57078675232</horizontal_fov>
        <image>
          <width>752 </width>
          <height> 480</height>
          <format>B8G8R8</format>
        </image>
        <clip>
          <near>0.01</near>
          <far>100</far>
        </clip>
      </camera>
      <plugin filename="libgazebo_ros_camera.so" name="monocular_camera_controller">
        <alwaysOn>true</alwaysOn>
        <updateRate>15.0</updateRate>
        <cameraName>back_camera</cameraName>
        <imageTopicName>image</imageTopicName>
        <cameraInfoTopicName>camera_info</cameraInfoTopicName>
        <frameName>back_camera_optical_frame</frameName>
        <hackBaseline>0</hackBaseline>
        <CxPrime>376.5</CxPrime>
        <Cx>376.5</Cx>
        <Cy>240.5</Cy>
        <focalLength>376.003507</focalLength>
        <!-- image_width / (2*tan(hfov_radian /2)) -->
        <distortionK1>0.0</distortionK1>
        <distortionK2>0.0</distortionK2>
        <distortionK3>0.0</distortionK3>
        <distortionT1>0.0</distortionT1>
        <distortionT2>0.0</distortionT2>
      </plugin>
    </sensor>
  </gazebo>
</robot>
